Workbook

Sheet Appendix 6.8 Contents
A2: This file contains the data tables for the sources and methods discussed Appendix 6.7 of Chapter 6
A4: Appendix Table 6.8.I.1: Measurement of the Business Sector
A5: Appendix Table 6.8.I.2: Measures of Noncorporate and Corporate Profits
A6: Appendix Table 6.8.I.3: Corrected Business Accounts
A7: Appendix Table 6.8.II.1: Accuracy of GPIM rules for chain-weighted capital stock estimates
A8: Appendix Table 6.8.II.2: Effects of different initial values for capital stock estimates
A9: Appendix Table 6.8.II.3: Effects of different depletion rates
A10: Appendix Table 6.8.II.4: Effects of the Great Depression and WWII
A11: Appendix Table 6.8.II.5: New Measures of Net and Gross Stocks
A12: Appendix Table 6.8.II.6: Measures of Corporate Inventories
A13: Appendix Table 6.8.II.7: Capacity Utilization and Final Capital Stock and Profit Rate Estimates

Sheet Appndx6.8.I.1-3
A1: Appendix Table 6.8.I.1: Measurement of the Business Sector
A2: All Tables from NIPA downloaded in 2011, and all sums in Bills=$, unless indicated otherwise
A3: Description | B3: Source | C3: Variable | D3: 1947 | E3: 1948 | F3: 1949 | G3: 1950 | H3: 1951 | I3: 1952 | J3: 1953 | K3: 1954 | L3: 1955 | M3: 1956 | N3: 1957 | O3: 1958 | P3: 1959 | Q3: 1960 | R3: 1961 | S3: 1962 | T3: 1963 | U3: 1964 | V3: 1965 | W3: 1966 | X3: 1967 | Y3: 1968 | Z3: 1969 | AA3: 1970 | AB3: 1971 | AC3: 1972 | AD3: 1973 | AE3: 1974 | AF3: 1975 | AG3: 1976 | AH3: 1977 | AI3: 1978 | AJ3: 1979 | AK3: 1980 | AL3: 1981 | AM3: 1982 | AN3: 1983 | AO3: 1984 | AP3: 1985 | AQ3: 1986 | AR3: 1987 | AS3: 1988 | AT3: 1989 | AU3: 1990 | AV3: 1991 | AW3: 1992 | AX3: 1993 | AY3: 1994 | AZ3: 1995 | BA3: 1996 | BB3: 1997 | BC3: 1998 | BD3: 1999 | BE3: 2000 | BF3: 2001 | BG3: 2002 | BH3: 2003 | BI3: 2004 | BJ3: 2005 | BK3: 2006 | BL3: 2007 | BM3: 2008 | BN3: 2009 | BO3: 2010 | BP3: 2011
A4: GDP | B4: T 1.7.5, 1 | C4: GDP | D4: 244.1 | E4: 269.1 | F4: 267.2 | G4: 293.7 | H4: 339.3 | I4: 358.3 | J4: 379.3 | K4: 380.4 | L4: 414.7 | M4: 437.4 | N4: 461.1 | O4: 467.2 | P4: 506.6 | Q4: 526.4 | R4: 544.8 | S4: 585.7 | T4: 617.8 | U4: 663.6 | V4: 719.1 | W4: 787.7 | X4: 832.4 | Y4: 909.8 | Z4: 984.4 | AA4: 1038.3 | AB4: 1126.8 | AC4: 1237.9 | AD4: 1382.3 | AE4: 1499.5 | AF4: 1637.7 | AG4: 1824.6 | AH4: 2030.1 | AI4: 2293.8 | AJ4: 2562.2 | AK4: 2788.1 | AL4: 3126.8 | AM4: 3253.2 | AN4: 3534.6 | AO4: 3930.9 | AP4: 4217.5 | AQ4: 4460.1 | AR4: 4736.4 | AS4: 5100.4 | AT4: 5482.1 | AU4: 5800.5 | AV4: 5992.1 | AW4: 6342.3 | AX4: 6667.4 | AY4: 7085.2 | AZ4: 7414.7 | BA4: 7838.5 | BB4: 8332.4 | BC4: 8793.5 | BD4: 9353.5 | BE4: 9951.5 | BF4: 10286.2 | BG4: 10642.3 | BH4: 11142.1 | BI4: 11853.3 | BJ4: 12623 | BK4: 13377.2 | BL4: 14028.7 | BM4: 14291.5 | BN4: 13973.7 | BO4: 14498.9 | BP4: 15075.7
A5: Less: SD (Stat. Discrepancy) | B5: T 1.7.5, 15 | C5: Less: SD | D5: 2.3 | E5: -0.5 | F5: 1.8 | G5: 1.4 | H5: 3.6 | I5: 2.7 | J5: 4 | K5: 3.1 | L5: 2.4 | M5: -1.8 | N5: -0.1 | O5: 1 | P5: 0.5 | Q5: -1 | R5: -0.6 | S5: 0.3 | T5: -0.8 | U5: 0.8 | V5: 1.5 | W5: 6.2 | X5: 4.5 | Y5: 4.3 | Z5: 2.9 | AA5: 6.9 | AB5: 11 | AC5: 8.9 | AD5: 8 | AE5: 9.8 | AF5: 16.3 | AG5: 23.5 | AH5: 21.2 | AI5: 26.1 | AJ5: 47 | AK5: 45.3 | AL5: 36.6 | AM5: 4.8 | AN5: 49.7 | AO5: 31.5 | AP5: 42.3 | AQ5: 67.7 | AR5: 32.9 | AS5: -9.5 | AT5: 56.1 | AU5: 84.2 | AV5: 79.7 | AW5: 110 | AX5: 135.8 | AY5: 108.8 | AZ5: 52.5 | BA5: 25.9 | BB5: -14 | BC5: -85.3 | BD5: -71.1 | BE5: -134 | BF5: -103.4 | BG5: -22.1 | BH5: 16.6 | BI5: -22.3 | BJ5: -95.1 | BK5: -242.3 | BL5: -12 | BM5: -2.4 | BN5: 118.3 | BO5: 23.3 | BP5: 31.9
A6: GDI | B6: T 1.10, 1 | C6: GDI | D6: 241.8 | E6: 269.6 | F6: 265.4 | G6: 292.3 | H6: 335.7 | I6: 355.6 | J6: 375.3 | K6: 377.3 | L6: 412.3 | M6: 439.2 | N6: 461.2 | O6: 466.2 | P6: 506.1 | Q6: 527.4 | R6: 545.4 | S6: 585.4 | T6: 618.6 | U6: 662.8 | V6: 717.6 | W6: 781.5 | X6: 827.9 | Y6: 905.5 | Z6: 981.5 | AA6: 1031.4 | AB6: 1115.8 | AC6: 1229 | AD6: 1374.3 | AE6: 1489.7 | AF6: 1621.4 | AG6: 1801.1 | AH6: 2008.9 | AI6: 2267.7 | AJ6: 2515.2 | AK6: 2742.8 | AL6: 3090.2 | AM6: 3248.4 | AN6: 3484.9 | AO6: 3899.4 | AP6: 4175.2 | AQ6: 4392.4 | AR6: 4703.5 | AS6: 5109.9 | AT6: 5426 | AU6: 5716.3 | AV6: 5912.4 | AW6: 6232.3 | AX6: 6531.6 | AY6: 6976.4 | AZ6: 7362.2 | BA6: 7812.6 | BB6: 8346.4 | BC6: 8878.8 | BD6: 9424.6 | BE6: 10085.5 | BF6: 10389.6 | BG6: 10664.4 | BH6: 11125.5 | BI6: 11875.6 | BJ6: 12718.1 | BK6: 13619.5 | BL6: 14040.7 | BM6: 14293.9 | BN6: 13855.4 | BO6: 14475.6 | BP6: 15043.8
A7: Less: EC (Empl. Comp., Paid) | B7: T 1.10, 2 | C7: Less: EC | D7: 130 | E7: 141.9 | F7: 141.8 | G7: 155.2 | H7: 181.4 | I7: 196.2 | J7: 210.2 | K7: 209.2 | L7: 225.8 | M7: 244.6 | N7: 257.6 | O7: 259.6 | P7: 281.1 | Q7: 296.6 | R7: 305.4 | S7: 327.2 | T7: 345.3 | U7: 370.7 | V7: 399.5 | W7: 442.6 | X7: 475.1 | Y7: 524.3 | Z7: 577.6 | AA7: 617.2 | AB7: 658.9 | AC7: 725.1 | AD7: 811.2 | AE7: 890.3 | AF7: 949.2 | AG7: 1059.4 | AH7: 1180.6 | AI7: 1335.6 | AJ7: 1498.4 | AK7: 1647.7 | AL7: 1819.8 | AM7: 1919.8 | AN7: 2035.7 | AO7: 2245.7 | AP7: 2412 | AQ7: 2559.4 | AR7: 2737 | AS7: 2955 | AT7: 3132.6 | AU7: 3328.6 | AV7: 3441.1 | AW7: 3634.4 | AX7: 3800.4 | AY7: 4002.5 | AZ7: 4199.3 | BA7: 4395.5 | BB7: 4670 | BC7: 5027.8 | BD7: 5359.2 | BE7: 5793.5 | BF7: 5984.5 | BG7: 6116.4 | BH7: 6388.3 | BI7: 6699.6 | BJ7: 7071.5 | BK7: 7483.6 | BL7: 7863 | BM7: 8079.1 | BN7: 7807.2 | BO7: 7977.2 | BP7: 8303.2
A8: Less: T (Taxes net of Subsidies) | B8: T 1.10, 9 - 10 | C8: Less: T | D8: 17.9 | E8: 19.4 | F8: 20.6 | G8: 22.4 | H8: 24 | I8: 26.7 | J8: 29 | K8: 29 | L8: 31.7 | M8: 33.8 | N8: 35.9 | O8: 36.8 | P8: 40 | Q8: 43.4 | R8: 45 | S8: 48.1 | T8: 51.2 | U8: 54.6 | V8: 57.7 | W8: 59.3 | X8: 64.1 | Y8: 72.2 | Z8: 79.4 | AA8: 86.6 | AB8: 95.8 | AC8: 101.3 | AD8: 112 | AE8: 121.6 | AF8: 130.8 | AG8: 141.3 | AH8: 152.6 | AI8: 162 | AJ8: 171.6 | AK8: 190.5 | AL8: 224.1 | AM8: 225.9 | AN8: 242 | AO8: 268.7 | AP8: 286.7 | AQ8: 298.5 | AR8: 317.2 | AS8: 345 | AT8: 371.5 | AU8: 398 | AV8: 429.6 | AW8: 453.3 | AX8: 466.4 | AY8: 512.7 | AZ8: 523.1 | BA8: 545.6 | BB8: 577.8 | BC8: 603.1 | BD8: 628.4 | BE8: 662.8 | BF8: 669 | BG8: 721.4 | BH8: 757.7 | BI8: 817 | BJ8: 869.3 | BK8: 935.4 | BL8: 972.6 | BM8: 985.7 | BN8: 963.5 | BO8: 998 | BP8: 1036.3
A9: Aggregate GOS | C9: Aggregate GOSnipa | D9: 93.9 | E9: 108.3 | F9: 103 | G9: 114.7 | H9: 130.3 | I9: 132.7 | J9: 136.1 | K9: 139.1 | L9: 154.8 | M9: 160.8 | N9: 167.7 | O9: 169.8 | P9: 185 | Q9: 187.4 | R9: 195 | S9: 210.1 | T9: 222.1 | U9: 237.5 | V9: 260.4 | W9: 279.6 | X9: 288.7 | Y9: 309 | Z9: 324.5 | AA9: 327.6 | AB9: 361.1 | AC9: 402.6 | AD9: 451.1 | AE9: 477.8 | AF9: 541.4 | AG9: 600.4 | AH9: 675.7 | AI9: 770.1 | AJ9: 845.2 | AK9: 904.6 | AL9: 1046.3 | AM9: 1102.7 | AN9: 1207.2 | AO9: 1385 | AP9: 1476.5 | AQ9: 1534.5 | AR9: 1649.3 | AS9: 1809.9 | AT9: 1921.9 | AU9: 1989.7 | AV9: 2041.7 | AW9: 2144.6 | AX9: 2264.8 | AY9: 2461.2 | AZ9: 2639.8 | BA9: 2871.5 | BB9: 3098.6 | BC9: 3247.9 | BD9: 3437 | BE9: 3629.2 | BF9: 3736.1 | BG9: 3826.6 | BH9: 3979.5 | BI9: 4359 | BJ9: 4777.3 | BK9: 5200.5 | BL9: 5205.1 | BM9: 5229.1 | BN9: 5084.7 | BO9: 5500.4 | BP9: 5704.3
A10: Less: CFC (Cons. of Fixed Capital) | B10: T 1.10, 23 | C10: Less: CFC | D10: 26.6 | E10: 28.5 | F10: 29.2 | G10: 29.9 | H10: 33.8 | I10: 36.3 | J10: 38.6 | K10: 40.6 | L10: 42.8 | M10: 47.1 | N10: 50.8 | O10: 53.3 | P10: 55.4 | Q10: 56.6 | R10: 58.2 | S10: 60.6 | T10: 63.3 | U10: 66.4 | V10: 70.7 | W10: 76.5 | X10: 82.9 | Y10: 90.4 | Z10: 99.2 | AA10: 108.3 | AB10: 117.8 | AC10: 127.2 | AD10: 140.8 | AE10: 163.7 | AF10: 190.4 | AG10: 208.2 | AH10: 231.8 | AI10: 261.4 | AJ10: 298.9 | AK10: 344.1 | AL10: 393.3 | AM10: 433.5 | AN10: 451.1 | AO10: 474.3 | AP10: 505.4 | AQ10: 538.5 | AR10: 571.1 | AS10: 611 | AT10: 651.5 | AU10: 691.2 | AV10: 724.4 | AW10: 744.4 | AX10: 778 | AY10: 819.2 | AZ10: 869.5 | BA10: 912.5 | BB10: 963.8 | BC10: 1020.5 | BD10: 1094.4 | BE10: 1184.3 | BF10: 1256.2 | BG10: 1305 | BH10: 1354.1 | BI10: 1432.8 | BJ10: 1541.4 | BK10: 1660.7 | BL10: 1767.5 | BM10: 1854.1 | BN10: 1866.3 | BO10: 1873.4 | BP10: 1936.8
A11: Aggregate NOS | B11: T 1.10, 11 | C11: Aggregate NOSnipa | D11: 67.3 | E11: 79.8 | F11: 73.8 | G11: 84.8 | H11: 96.5 | I11: 96.4 | J11: 97.5 | K11: 98.5 | L11: 112 | M11: 113.7 | N11: 116.9 | O11: 116.5 | P11: 129.6 | Q11: 130.8 | R11: 136.8 | S11: 149.5 | T11: 158.8 | U11: 171.1 | V11: 189.7 | W11: 203.1 | X11: 205.8 | Y11: 218.6 | Z11: 225.3 | AA11: 219.3 | AB11: 243.3 | AC11: 275.4 | AD11: 310.3 | AE11: 314.1 | AF11: 351 | AG11: 392.2 | AH11: 443.9 | AI11: 508.7 | AJ11: 546.3 | AK11: 560.5 | AL11: 653 | AM11: 669.2 | AN11: 756.1 | AO11: 910.7 | AP11: 971.1 | AQ11: 996 | AR11: 1078.2 | AS11: 1198.9 | AT11: 1270.4 | AU11: 1298.5 | AV11: 1317.3 | AW11: 1400.2 | AX11: 1486.8 | AY11: 1642 | AZ11: 1770.3 | BA11: 1959 | BB11: 2134.8 | BC11: 2227.4 | BD11: 2342.6 | BE11: 2444.9 | BF11: 2479.9 | BG11: 2521.6 | BH11: 2625.4 | BI11: 2926.2 | BJ11: 3235.9 | BK11: 3539.8 | BL11: 3437.6 | BM11: 3375 | BN11: 3218.4 | BO11: 3627 | BP11: 3767.5
A12: Net interest and miscellaneous payments, domestic industries | B12: T 1.10, 13 | C12: Net Int | D12: 2.4 | E12: 2.5 | F12: 2.8 | G12: 3.1 | H12: 3.5 | I12: 4 | J12: 4.6 | K12: 5.4 | L12: 6.1 | M12: 6.8 | N12: 8 | O12: 9.4 | P12: 9.5 | Q12: 10.4 | R12: 12.1 | S12: 13.8 | T12: 14.7 | U12: 16.9 | V12: 19.1 | W12: 21.9 | X12: 24.9 | Y12: 26.7 | Z12: 33.2 | AA12: 39.9 | AB12: 44.2 | AC12: 48.9 | AD12: 57.5 | AE12: 72.7 | AF12: 83.2 | AG12: 85.2 | AH12: 99.8 | AI12: 116.2 | AJ12: 141.5 | AK12: 183 | AL12: 228.9 | AM12: 267 | AN12: 283.1 | AO12: 327.1 | AP12: 352.8 | AQ12: 387.2 | AR12: 395.7 | AS12: 418.1 | AT12: 474 | AU12: 483.6 | AV12: 462 | AW12: 428.7 | AX12: 407 | AY12: 412.1 | AZ12: 417.5 | BA12: 437.2 | BB12: 487.3 | BC12: 560.2 | BD12: 569.9 | BE12: 642.5 | BF12: 656.9 | BG12: 609.6 | BH12: 595.5 | BI12: 569.3 | BJ12: 678.9 | BK12: 830.1 | BL12: 952.1 | BM12: 1096.8 | BN12: 841.9 | BO12: 753 | BP12: 706.4
A13: Business current transfer payments (net) | B13: T 1.10, 14 | C13: Curr Transfers | D13: 0.7 | E13: 0.7 | F13: 0.7 | G13: 0.9 | H13: 1.2 | I13: 1.3 | J13: 1.2 | K13: 1 | L13: 1.4 | M13: 1.7 | N13: 1.9 | O13: 1.8 | P13: 1.8 | Q13: 1.9 | R13: 2 | S13: 2.2 | T13: 2.7 | U13: 3.1 | V13: 3.6 | W13: 3.5 | X13: 3.8 | Y13: 4.3 | Z13: 4.9 | AA13: 4.5 | AB13: 4.3 | AC13: 4.9 | AD13: 6 | AE13: 7.1 | AF13: 9.4 | AG13: 9.5 | AH13: 8.5 | AI13: 10.8 | AJ13: 13.3 | AK13: 14.7 | AL13: 17.9 | AM13: 20.6 | AN13: 22.6 | AO13: 30.3 | AP13: 35.2 | AQ13: 36.9 | AR13: 34.1 | AS13: 33.6 | AT13: 39.2 | AU13: 40.1 | AV13: 39.9 | AW13: 40.7 | AX13: 40.5 | AY13: 41.9 | AZ13: 45.8 | BA13: 53.8 | BB13: 51.3 | BC13: 65.2 | BD13: 69 | BE13: 87 | BF13: 101.3 | BG13: 82.4 | BH13: 76.1 | BI13: 81.7 | BJ13: 95.9 | BK13: 83 | BL13: 103.3 | BM13: 123 | BN13: 133.4 | BO13: 140 | BP13: 132.6
A14: Proprietors' income with inventory valuation and capital consumption adjustments | B14: T 1.10, 15 | C14: Prop Inc w/IVA and CCAdj | D14: 34.5 | E14: 39.2 | F14: 34.6 | G14: 37.5 | H14: 42.7 | I14: 43.1 | J14: 42 | K14: 42.3 | L14: 44.3 | M14: 45.9 | N14: 47.8 | O14: 50.2 | P14: 50.3 | Q14: 50.7 | R14: 53.2 | S14: 55.3 | T14: 56.5 | U14: 59.4 | V14: 63.9 | W14: 68.2 | X14: 69.8 | Y14: 74.2 | Z14: 77.5 | AA14: 78.5 | AB14: 84.7 | AC14: 96 | AD14: 113.6 | AE14: 113.5 | AF14: 119.6 | AG14: 132.2 | AH14: 146 | AI14: 167.5 | AJ14: 181.1 | AK14: 173.5 | AL14: 181.6 | AM14: 174.8 | AN14: 190.7 | AO14: 233.1 | AP14: 246.1 | AQ14: 262.6 | AR14: 294.2 | AS14: 334.8 | AT14: 351.6 | AU14: 365.1 | AV14: 367.3 | AW14: 414.9 | AX14: 449.6 | AY14: 485.1 | AZ14: 516 | BA14: 583.7 | BB14: 628.2 | BC14: 687.5 | BD14: 746.8 | BE14: 817.5 | BF14: 870.7 | BG14: 890.3 | BH14: 930.6 | BI14: 1033.8 | BJ14: 1069.8 | BK14: 1133 | BL14: 1090.4 | BM14: 1097.9 | BN14: 979.4 | BO14: 1103.4 | BP14: 1157.3
A15: Rental income of persons with capital consumption adjustment | B15: T 1.10, 16 | C15: Rental Inc w/ CCAdj | D15: 7.2 | E15: 7.8 | F15: 8.1 | G15: 9.1 | H15: 10 | I15: 11.2 | J15: 12.4 | K15: 13.4 | L15: 13.8 | M15: 14.1 | N15: 14.5 | O15: 15.2 | P15: 16 | Q15: 17 | R15: 17.7 | S15: 18.6 | T15: 19.3 | U15: 19.4 | V15: 19.9 | W15: 20.5 | X15: 20.9 | Y15: 20.6 | Z15: 20.9 | AA15: 21.1 | AB15: 22.2 | AC15: 23.1 | AD15: 23.9 | AE15: 24 | AF15: 23.4 | AG15: 22.1 | AH15: 19.6 | AI15: 20.9 | AJ15: 22.6 | AK15: 28.5 | AL15: 36.5 | AM15: 38.1 | AN15: 38.2 | AO15: 40 | AP15: 41.9 | AQ15: 33.8 | AR15: 34.2 | AS15: 40.2 | AT15: 42.4 | AU15: 49.8 | AV15: 61.6 | AW15: 84.6 | AX15: 114.1 | AY15: 142.9 | AZ15: 154.6 | BA15: 170.4 | BB15: 176.5 | BC15: 191.5 | BD15: 208.2 | BE15: 215.3 | BF15: 232.4 | BG15: 218.7 | BH15: 204.2 | BI15: 198.4 | BJ15: 178.2 | BK15: 146.5 | BL15: 143.7 | BM15: 231.6 | BN15: 289.7 | BO15: 349.2 | BP15: 409.7
A16: Corporate profits with inventory valuation and capital consumption adjustments, domestic industries | B16: T 1.10, 17 | C16: Corp Profit w/IVA and CCAdj | D16: 22.5 | E16: 29.6 | F16: 27.6 | G16: 34.4 | H16: 39.1 | I16: 37 | J16: 37.3 | K16: 36.4 | L16: 46.6 | M16: 45.2 | N16: 44.5 | O16: 39.9 | P16: 51.1 | Q16: 50 | R16: 50.9 | S16: 58.6 | T16: 64.3 | U16: 71.1 | V16: 81.8 | W16: 88 | X16: 85.4 | Y16: 91.6 | Z16: 87.9 | AA16: 75.4 | AB16: 88.2 | AC16: 101.9 | AD16: 109.6 | AE16: 97.7 | AF16: 118.7 | AG16: 145.1 | AH16: 172.7 | AI16: 195.6 | AJ16: 190.7 | AK16: 166 | AL16: 193.6 | AM16: 173.1 | AN16: 224.8 | AO16: 282 | AP16: 294.4 | AQ16: 274.7 | AR16: 319.8 | AS16: 369.6 | AT16: 358.4 | AU16: 358.4 | AV16: 380.8 | AW16: 423.1 | AX16: 466.8 | AY16: 550.3 | AZ16: 623.2 | BA16: 699.5 | BB16: 777.3 | BC16: 709.7 | BD16: 734.8 | BE16: 673.6 | BF16: 614.5 | BG16: 714.3 | BH16: 812 | BI16: 1041.9 | BJ16: 1216.6 | BK16: 1351.5 | BL16: 1159.8 | BM16: 841.8 | BN16: 989.5 | BO16: 1300.9 | BP16: 1388.1
A17: Current surplus of government enterprises | B17: T 1.10, 22 | C17: Curr Surplus Gov. Enterp | D17: 0 | E17: 0 | F17: 0 | G17: 0 | H17: 0 | I17: 0 | J17: 0 | K17: 0 | L17: 0 | M17: 0 | N17: 0 | O17: 0 | P17: 1 | Q17: 0.9 | R17: 0.8 | S17: 0.9 | T17: 1.4 | U17: 1.3 | V17: 1.3 | W17: 1 | X17: 0.9 | Y17: 1.2 | Z17: 1 | AA17: 0 | AB17: -0.2 | AC17: 0.5 | AD17: -0.4 | AE17: -0.9 | AF17: -3.2 | AG17: -1.8 | AH17: -2.7 | AI17: -2.2 | AJ17: -2.9 | AK17: -5.1 | AL17: -5.6 | AM17: -4.5 | AN17: -3.2 | AO17: -1.9 | AP17: 0.6 | AQ17: 0.9 | AR17: 0.2 | AS17: 2.6 | AT17: 4.9 | AU17: 1.6 | AV17: 5.7 | AW17: 8.2 | AX17: 8.7 | AY17: 9.6 | AZ17: 13.1 | BA17: 14.4 | BB17: 14.1 | BC17: 13.3 | BD17: 14.1 | BE17: 9.1 | BF17: 4 | BG17: 6.3 | BH17: 7 | BI17: 1.2 | BJ17: -3.5 | BK17: -4.2 | BL17: -11.8 | BM17: -16 | BN17: -15.6 | BO17: -19.5 | BP17: -26.5
A19: GVAhh | B19: T 1.3.5, 6 | C19: GVAhh | D19: 9.7 | E19: 10.6 | F19: 11.6 | G19: 13 | H19: 14.6 | I19: 16.4 | J19: 18.3 | K19: 20 | L19: 22 | M19: 23.9 | N19: 25.8 | O19: 27.8 | P19: 30.1 | Q19: 32.6 | R19: 34.6 | S19: 37 | T19: 39.1 | U19: 41.2 | V19: 43.6 | W19: 46.2 | X19: 49.1 | Y19: 51.9 | Z19: 56 | AA19: 59.8 | AB19: 65.5 | AC19: 70.8 | AD19: 76.5 | AE19: 83 | AF19: 90.8 | AG19: 98.7 | AH19: 107.9 | AI19: 121.3 | AJ19: 136 | AK19: 156.5 | AL19: 177.8 | AM19: 196.7 | AN19: 212.5 | AO19: 231 | AP19: 250.3 | AQ19: 268 | AR19: 288 | AS19: 313.1 | AT19: 337.2 | AU19: 363.3 | AV19: 383.7 | AW19: 405.3 | AX19: 428.3 | AY19: 461.3 | AZ19: 492.2 | BA19: 519.8 | BB19: 550.9 | BC19: 583.9 | BD19: 628.4 | BE19: 673.5 | BF19: 719.5 | BG19: 746 | BH19: 762.7 | BI19: 806 | BJ19: 864.4 | BK19: 924.8 | BL19: 968.1 | BM19: 1042.8 | BN19: 1048.3 | BO19: 1038.5 | BP19: 1055.2
A20: Less: EChh | B20: GVAhh - GVAooh | C20: Less: EChh | D20: 2.4 | E20: 2.3 | F20: 2.4 | G20: 2.6 | H20: 2.6 | I20: 2.6 | J20: 2.7 | K20: 2.6 | L20: 3 | M20: 3.3 | N20: 3.4 | O20: 3.4 | P20: 3.6 | Q20: 3.8 | R20: 3.7 | S20: 3.8 | T20: 3.8 | U20: 3.9 | V20: 3.9 | W20: 4 | X20: 4.2 | Y20: 4.4 | Z20: 4.4 | AA20: 4.5 | AB20: 4.5 | AC20: 4.6 | AD20: 4.8 | AE20: 4.6 | AF20: 4.7 | AG20: 5.4 | AH20: 5.9 | AI20: 6.5 | AJ20: 6.4 | AK20: 6 | AL20: 6.1 | AM20: 6.3 | AN20: 6.2 | AO20: 7.3 | AP20: 7.4 | AQ20: 7.8 | AR20: 7.7 | AS20: 8.4 | AT20: 9 | AU20: 9.3 | AV20: 9.2 | AW20: 10.3 | AX20: 10.9 | AY20: 11.3 | AZ20: 12.1 | BA20: 12.2 | BB20: 12.2 | BC20: 14.2 | BD20: 12.9 | BE20: 13.8 | BF20: 13 | BG20: 12.8 | BH20: 14.3 | BI20: 15.1 | BJ20: 15.4 | BK20: 16.5 | BL20: 18.1 | BM20: 19.2 | BN20: 17.5 | BO20: 15.3 | BP20: 16.5
A21: Less: Thh | B21: T 7.12, 135-136 | C21: Less: Thh | D21: 1.3 | E21: 1.4 | F21: 1.6 | G21: 1.8 | H21: 2 | I21: 2.2 | J21: 2.5 | K21: 2.7 | L21: 3.1 | M21: 3.6 | N21: 4 | O21: 4.5 | P21: 4.8 | Q21: 5.3 | R21: 5.9 | S21: 6.4 | T21: 7 | U21: 7.7 | V21: 8.3 | W21: 9 | X21: 10.1 | Y21: 11.4 | Z21: 12.7 | AA21: 14.4 | AB21: 15.8 | AC21: 17.1 | AD21: 18.5 | AE21: 19.8 | AF21: 21.8 | AG21: 24.1 | AH21: 26.5 | AI21: 27.1 | AJ21: 28 | AK21: 30.5 | AL21: 33.7 | AM21: 36.7 | AN21: 39.2 | AO21: 42.2 | AP21: 44.9 | AQ21: 47.7 | AR21: 52.2 | AS21: 55.6 | AT21: 60.1 | AU21: 63.8 | AV21: 68.4 | AW21: 70.6 | AX21: 70.6 | AY21: 73.8 | AZ21: 74.1 | BA21: 76.5 | BB21: 79.2 | BC21: 80.8 | BD21: 83.4 | BE21: 86.2 | BF21: 91 | BG21: 98.4 | BH21: 104.1 | BI21: 110.2 | BJ21: 114.7 | BK21: 123.9 | BL21: 126.1 | BM21: 133.7 | BN21: 142.3 | BO21: 143.6 | BP21: 146.3
A22: GOShh | C22: GOShh | D22: 6 | E22: 6.9 | F22: 7.6 | G22: 8.6 | H22: 10 | I22: 11.6 | J22: 13.1 | K22: 14.7 | L22: 15.9 | M22: 17 | N22: 18.4 | O22: 19.9 | P22: 21.7 | Q22: 23.5 | R22: 25 | S22: 26.8 | T22: 28.3 | U22: 29.6 | V22: 31.4 | W22: 33.2 | X22: 34.8 | Y22: 36.1 | Z22: 38.9 | AA22: 40.9 | AB22: 45.2 | AC22: 49.1 | AD22: 53.2 | AE22: 58.6 | AF22: 64.3 | AG22: 69.2 | AH22: 75.5 | AI22: 87.7 | AJ22: 101.6 | AK22: 120 | AL22: 138 | AM22: 153.7 | AN22: 167.1 | AO22: 181.5 | AP22: 198 | AQ22: 212.5 | AR22: 228.1 | AS22: 249.1 | AT22: 268.1 | AU22: 290.2 | AV22: 306.1 | AW22: 324.4 | AX22: 346.8 | AY22: 376.2 | AZ22: 406 | BA22: 431.1 | BB22: 459.5 | BC22: 488.9 | BD22: 532.1 | BE22: 573.5 | BF22: 615.5 | BG22: 634.8 | BH22: 644.3 | BI22: 680.7 | BJ22: 734.3 | BK22: 784.4 | BL22: 823.9 | BM22: 889.9 | BN22: 888.5 | BO22: 879.6 | BP22: 892.4
A23: Less: CFChh | B23: T 7.12, 140 | C23: Less: CFChh | D23: 2 | E23: 2.3 | F23: 2.5 | G23: 2.8 | H23: 3.2 | I23: 3.4 | J23: 3.7 | K23: 3.9 | L23: 4.2 | M23: 4.5 | N23: 4.8 | O23: 5 | P23: 5.2 | Q23: 5.5 | R23: 5.6 | S23: 5.8 | T23: 6 | U23: 6.3 | V23: 6.8 | W23: 7.3 | X23: 7.8 | Y23: 8.5 | Z23: 9.5 | AA23: 10.1 | AB23: 11.1 | AC23: 12.3 | AD23: 13.9 | AE23: 16 | AF23: 17.9 | AG23: 19.7 | AH23: 22.5 | AI23: 26.3 | AJ23: 30.5 | AK23: 35 | AL23: 38.8 | AM23: 41.4 | AN23: 43 | AO23: 45.5 | AP23: 47.9 | AQ23: 51.2 | AR23: 54.9 | AS23: 58.9 | AT23: 62.9 | AU23: 66.4 | AV23: 68.9 | AW23: 71.3 | AX23: 75.8 | AY23: 80.9 | AZ23: 86.6 | BA23: 91.2 | BB23: 96.6 | BC23: 102.3 | BD23: 110 | BE23: 118.5 | BF23: 127.7 | BG23: 135 | BH23: 146.2 | BI23: 163.5 | BJ23: 181.4 | BK23: 199.2 | BL23: 208 | BM23: 209.5 | BN23: 204.5 | BO23: 205.5 | BP23: 209.5
A24: NOShh | C24: NOShh | D24: 4 | E24: 4.6 | F24: 5.1 | G24: 5.8 | H24: 6.8 | I24: 8.2 | J24: 9.4 | K24: 10.8 | L24: 11.7 | M24: 12.5 | N24: 13.6 | O24: 14.9 | P24: 16.5 | Q24: 18 | R24: 19.4 | S24: 21 | T24: 22.3 | U24: 23.3 | V24: 24.6 | W24: 25.9 | X24: 27 | Y24: 27.6 | Z24: 29.4 | AA24: 30.8 | AB24: 34.1 | AC24: 36.8 | AD24: 39.3 | AE24: 42.6 | AF24: 46.4 | AG24: 49.5 | AH24: 53 | AI24: 61.4 | AJ24: 71.1 | AK24: 85 | AL24: 99.2 | AM24: 112.3 | AN24: 124.1 | AO24: 136 | AP24: 150.1 | AQ24: 161.3 | AR24: 173.2 | AS24: 190.2 | AT24: 205.2 | AU24: 223.8 | AV24: 237.2 | AW24: 253.1 | AX24: 271 | AY24: 295.3 | AZ24: 319.4 | BA24: 339.9 | BB24: 362.9 | BC24: 386.6 | BD24: 422.1 | BE24: 455 | BF24: 487.8 | BG24: 499.8 | BH24: 498.1 | BI24: 517.2 | BJ24: 552.9 | BK24: 585.2 | BL24: 615.9 | BM24: 680.4 | BN24: 684 | BO24: 674.1 | BP24: 682.9
A25: Net interest | B25: T 7.12, 137 | C25: Net Int | D25: 1.1 | E25: 1.3 | F25: 1.4 | G25: 1.6 | H25: 1.9 | I25: 2.2 | J25: 2.5 | K25: 2.9 | L25: 3.3 | M25: 3.9 | N25: 4.6 | O25: 5.2 | P25: 5.9 | Q25: 6.6 | R25: 7.2 | S25: 8.1 | T25: 8.8 | U25: 9.8 | V25: 10.7 | W25: 11.5 | X25: 12.2 | Y25: 13.1 | Z25: 14.5 | AA25: 15.9 | AB25: 18.2 | AC25: 21 | AD25: 24 | AE25: 27.5 | AF25: 32.1 | AG25: 36.1 | AH25: 42.6 | AI25: 50.3 | AJ25: 60.2 | AK25: 71.5 | AL25: 83.3 | AM25: 99.3 | AN25: 112.7 | AO25: 125.6 | AP25: 142.2 | AQ25: 156.6 | AR25: 165.9 | AS25: 176.2 | AT25: 190.2 | AU25: 205 | AV25: 211.9 | AW25: 213.6 | AX25: 204.7 | AY25: 204.9 | AZ25: 221.9 | BA25: 231.3 | BB25: 246.2 | BC25: 257.7 | BD25: 276.1 | BE25: 303.2 | BF25: 324.9 | BG25: 341.2 | BH25: 348.2 | BI25: 371.9 | BJ25: 423.9 | BK25: 491.2 | BL25: 538.9 | BM25: 547.2 | BN25: 488.8 | BO25: 434 | BP25: 401.1
A26: Current transfer payments | B26: T 7.12, 138 | C26: Curr Transfers | D26: 0 | E26: 0 | F26: 0 | G26: 0 | H26: 0 | I26: 0 | J26: 0 | K26: 0 | L26: 0 | M26: 0 | N26: 0 | O26: 0 | P26: 0 | Q26: 0 | R26: -0.1 | S26: -0.1 | T26: -0.1 | U26: -0.1 | V26: -0.1 | W26: 0 | X26: 0 | Y26: 0 | Z26: 0 | AA26: 0 | AB26: 0.1 | AC26: 0.2 | AD26: 0.1 | AE26: -0.3 | AF26: -0.2 | AG26: 0.1 | AH26: 0.4 | AI26: 0.5 | AJ26: -0.1 | AK26: -0.3 | AL26: 0.2 | AM26: 0 | AN26: -0.1 | AO26: -0.1 | AP26: -0.3 | AQ26: 1 | AR26: 1.6 | AS26: 0.7 | AT26: -0.9 | AU26: -0.8 | AV26: -0.6 | AW26: -1.4 | AX26: 1.5 | AY26: 1.8 | AZ26: 1.7 | BA26: -0.7 | BB26: 4.6 | BC26: 1.8 | BD26: 2 | BE26: 0.8 | BF26: -1 | BG26: 2.6 | BH26: 4.4 | BI26: 5.8 | BJ26: 11.3 | BK26: 10.7 | BL26: 8.9 | BM26: 3.2 | BN26: 5.7 | BO26: 3.9 | BP26: -2
A27: Rental income of persons with capital consumption adjustment | B27: T 7.12, 139 | C27: Rental Inc w/ CCAdj | D27: 3 | E27: 3.2 | F27: 3.6 | G27: 4.3 | H27: 4.9 | I27: 5.9 | J27: 7 | K27: 8 | L27: 8.4 | M27: 8.6 | N27: 9.1 | O27: 9.6 | P27: 10.5 | Q27: 11.5 | R27: 12.2 | S27: 13 | T27: 13.5 | U27: 13.6 | V27: 13.9 | W27: 14.4 | X27: 14.9 | Y27: 14.5 | Z27: 14.9 | AA27: 14.8 | AB27: 15.8 | AC27: 15.7 | AD27: 15.1 | AE27: 15.5 | AF27: 14.6 | AG27: 13.3 | AH27: 9.9 | AI27: 10.5 | AJ27: 11 | AK27: 13.8 | AL27: 15.7 | AM27: 13 | AN27: 11.4 | AO27: 10.6 | AP27: 8.2 | AQ27: 3.7 | AR27: 5.7 | AS27: 13.4 | AT27: 16 | AU27: 19.4 | AV27: 25.9 | AW27: 40.9 | AX27: 64.8 | AY27: 88.8 | AZ27: 95.9 | BA27: 109.2 | BB27: 112.1 | BC27: 127.3 | BD27: 144 | BE27: 151 | BF27: 163.9 | BG27: 156 | BH27: 145.5 | BI27: 139.5 | BJ27: 117.9 | BK27: 83.4 | BL27: 68.1 | BM27: 130 | BN27: 189.5 | BO27: 236.2 | BP27: 283.9
A29: GVAnpish | B29: T 1.3.5, 7 | C29: GVAnpish | D29: 3.5 | E29: 4 | F29: 4.4 | G29: 4.8 | H29: 5.3 | I29: 5.7 | J29: 6.3 | K29: 6.8 | L29: 7.4 | M29: 8.1 | N29: 8.9 | O29: 9.7 | P29: 10.6 | Q29: 12 | R29: 12.8 | S29: 14 | T29: 15.2 | U29: 16.5 | V29: 18.2 | W29: 20.4 | X29: 22.7 | Y29: 25.6 | Z29: 29.4 | AA29: 32.8 | AB29: 36.7 | AC29: 40.5 | AD29: 45.2 | AE29: 50.6 | AF29: 56.7 | AG29: 61.8 | AH29: 67.6 | AI29: 75.6 | AJ29: 84.8 | AK29: 97 | AL29: 109.7 | AM29: 122.7 | AN29: 135.6 | AO29: 149.3 | AP29: 159.8 | AQ29: 174.3 | AR29: 194.8 | AS29: 216.6 | AT29: 237 | AU29: 260.6 | AV29: 282.2 | AW29: 305.9 | AX29: 323.8 | AY29: 338.7 | AZ29: 359.9 | BA29: 377.2 | BB29: 398.3 | BC29: 426.3 | BD29: 454.5 | BE29: 483.7 | BF29: 513.4 | BG29: 552.1 | BH29: 584.5 | BI29: 617.7 | BJ29: 642 | BK29: 678.1 | BL29: 717.8 | BM29: 762.9 | BN29: 796.5 | BO29: 812.7 | BP29: 836.9
A30: Less: ECnpish | B30: T1.3.5, 7 - T7.12, 141 - T7.9, 14 | C30: Less: ECnpish | D30: 2.9 | E30: 3.3 | F30: 3.7 | G30: 4 | H30: 4.4 | I30: 4.7 | J30: 5.3 | K30: 5.7 | L30: 6.2 | M30: 6.8 | N30: 7.5 | O30: 8.2 | P30: 9 | Q30: 10.3 | R30: 11 | S30: 12.1 | T30: 13.1 | U30: 14.2 | V30: 15.6 | W30: 17.6 | X30: 19.5 | Y30: 22.1 | Z30: 25.4 | AA30: 28.3 | AB30: 31.6 | AC30: 34.7 | AD30: 38.8 | AE30: 43.2 | AF30: 48 | AG30: 52.4 | AH30: 57.3 | AI30: 64 | AJ30: 71.7 | AK30: 81.7 | AL30: 92 | AM30: 102.6 | AN30: 113.3 | AO30: 124.2 | AP30: 133.9 | AQ30: 146.2 | AR30: 165.2 | AS30: 184.5 | AT30: 202.3 | AU30: 223.4 | AV30: 242.2 | AW30: 263.2 | AX30: 277.5 | AY30: 291.6 | AZ30: 310.2 | BA30: 325.2 | BB30: 343.5 | BC30: 367.9 | BD30: 392.5 | BE30: 418.1 | BF30: 443.9 | BG30: 479.4 | BH30: 509.4 | BI30: 538.9 | BJ30: 559.4 | BK30: 590.9 | BL30: 620.5 | BM30: 656.5 | BN30: 687.3 | BO30: 703.6 | BP30: 724.5
A31: Less: Tnpish | B31: T 7.12, 141 | C31: Less: Tnpish | D31: 0.1 | E31: 0.1 | F31: 0.1 | G31: 0.1 | H31: 0.1 | I31: 0.2 | J31: 0.2 | K31: 0.2 | L31: 0.2 | M31: 0.2 | N31: 0.2 | O31: 0.3 | P31: 0.3 | Q31: 0.3 | R31: 0.3 | S31: 0.4 | T31: 0.4 | U31: 0.4 | V31: 0.5 | W31: 0.5 | X31: 0.6 | Y31: 0.6 | Z31: 0.7 | AA31: 0.8 | AB31: 0.9 | AC31: 1 | AD31: 1 | AE31: 1.1 | AF31: 1.1 | AG31: 1.2 | AH31: 1.3 | AI31: 1.3 | AJ31: 1.3 | AK31: 1.3 | AL31: 1.5 | AM31: 1.7 | AN31: 1.8 | AO31: 2 | AP31: 2.1 | AQ31: 2.2 | AR31: 2.5 | AS31: 2.6 | AT31: 2.9 | AU31: 3.1 | AV31: 3.4 | AW31: 3.6 | AX31: 3.6 | AY31: 3.9 | AZ31: 3.9 | BA31: 4 | BB31: 4.3 | BC31: 4.4 | BD31: 4.7 | BE31: 4.9 | BF31: 5.1 | BG31: 5.6 | BH31: 5.9 | BI31: 6.3 | BJ31: 6.6 | BK31: 7.1 | BL31: 7.8 | BM31: 8.3 | BN31: 8.8 | BO31: 8.8 | BP31: 9
A32: GOSnpish | C32: GOSnpish | D32: 0.5 | E32: 0.6 | F32: 0.6 | G32: 0.7 | H32: 0.8 | I32: 0.8 | J32: 0.8 | K32: 0.9 | L32: 1 | M32: 1.1 | N32: 1.2 | O32: 1.2 | P32: 1.3 | Q32: 1.4 | R32: 1.5 | S32: 1.5 | T32: 1.7 | U32: 1.9 | V32: 2.1 | W32: 2.3 | X32: 2.6 | Y32: 2.9 | Z32: 3.3 | AA32: 3.7 | AB32: 4.2 | AC32: 4.8 | AD32: 5.4 | AE32: 6.3 | AF32: 7.6 | AG32: 8.2 | AH32: 9 | AI32: 10.3 | AJ32: 11.8 | AK32: 14 | AL32: 16.2 | AM32: 18.4 | AN32: 20.5 | AO32: 23.1 | AP32: 23.8 | AQ32: 25.9 | AR32: 27.1 | AS32: 29.5 | AT32: 31.8 | AU32: 34.1 | AV32: 36.6 | AW32: 39.1 | AX32: 42.7 | AY32: 43.2 | AZ32: 45.8 | BA32: 48 | BB32: 50.5 | BC32: 54 | BD32: 57.3 | BE32: 60.7 | BF32: 64.4 | BG32: 67.1 | BH32: 69.2 | BI32: 72.5 | BJ32: 76 | BK32: 80.1 | BL32: 89.5 | BM32: 98.1 | BN32: 100.4 | BO32: 100.3 | BP32: 103.4
A33: Less: CFCnpish | B33: T 7.12, 144 | C33: Less: CFCnpish | D33: 0.4 | E33: 0.5 | F33: 0.5 | G33: 0.6 | H33: 0.7 | I33: 0.7 | J33: 0.8 | K33: 0.8 | L33: 0.9 | M33: 1 | N33: 1.1 | O33: 1.2 | P33: 1.2 | Q33: 1.3 | R33: 1.4 | S33: 1.5 | T33: 1.6 | U33: 1.7 | V33: 1.8 | W33: 2 | X33: 2.2 | Y33: 2.4 | Z33: 2.7 | AA33: 3 | AB33: 3.3 | AC33: 3.7 | AD33: 4.3 | AE33: 5.1 | AF33: 6 | AG33: 6.6 | AH33: 7.3 | AI33: 8.2 | AJ33: 9.3 | AK33: 10.6 | AL33: 11.8 | AM33: 12.9 | AN33: 13.6 | AO33: 14.4 | AP33: 15.2 | AQ33: 16.2 | AR33: 17.3 | AS33: 18.6 | AT33: 20.2 | AU33: 22.1 | AV33: 23.8 | AW33: 25.5 | AX33: 27.2 | AY33: 28.5 | AZ33: 29.8 | BA33: 30.7 | BB33: 32.2 | BC33: 34.8 | BD33: 37.8 | BE33: 41.3 | BF33: 44.6 | BG33: 47.7 | BH33: 51.2 | BI33: 55.4 | BJ33: 60.1 | BK33: 65 | BL33: 73.5 | BM33: 81.1 | BN33: 84.2 | BO33: 85.4 | BP33: 88.2
A34: NOSnpish | C34: NOSnpish | D34: 0.1 | E34: 0.1 | F34: 0.1 | G34: 0.1 | H34: 0.1 | I34: 0.1 | J34: 0 | K34: 0.1 | L34: 0.1 | M34: 0.1 | N34: 0.1 | O34: 0 | P34: 0.1 | Q34: 0.1 | R34: 0.1 | S34: 0 | T34: 0.1 | U34: 0.2 | V34: 0.3 | W34: 0.3 | X34: 0.4 | Y34: 0.5 | Z34: 0.6 | AA34: 0.7 | AB34: 0.9 | AC34: 1.1 | AD34: 1.1 | AE34: 1.2 | AF34: 1.6 | AG34: 1.6 | AH34: 1.7 | AI34: 2.1 | AJ34: 2.5 | AK34: 3.4 | AL34: 4.4 | AM34: 5.5 | AN34: 6.9 | AO34: 8.7 | AP34: 8.6 | AQ34: 9.7 | AR34: 9.8 | AS34: 10.9 | AT34: 11.6 | AU34: 12 | AV34: 12.8 | AW34: 13.6 | AX34: 15.5 | AY34: 14.7 | AZ34: 16 | BA34: 17.3 | BB34: 18.3 | BC34: 19.2 | BD34: 19.5 | BE34: 19.4 | BF34: 19.8 | BG34: 19.4 | BH34: 18 | BI34: 17.1 | BJ34: 15.9 | BK34: 15.1 | BL34: 16 | BM34: 17 | BN34: 16.2 | BO34: 14.9 | BP34: 15.2
A35: Net Interest | B35: T 7.12, 141 | C35: Net Int | D35: 0.1 | E35: 0.1 | F35: 0.1 | G35: 0.1 | H35: 0.1 | I35: 0.1 | J35: 0.1 | K35: 0.1 | L35: 0.1 | M35: 0.1 | N35: 0.1 | O35: 0.1 | P35: 0.1 | Q35: 0.1 | R35: 0.1 | S35: 0.1 | T35: 0.1 | U35: 0.2 | V35: 0.2 | W35: 0.3 | X35: 0.4 | Y35: 0.5 | Z35: 0.6 | AA35: 0.7 | AB35: 0.8 | AC35: 0.8 | AD35: 0.9 | AE35: 1.1 | AF35: 1.4 | AG35: 1.4 | AH35: 1.5 | AI35: 1.9 | AJ35: 2.3 | AK35: 3 | AL35: 3.7 | AM35: 4.8 | AN35: 5.9 | AO35: 7.7 | AP35: 7.5 | AQ35: 8.6 | AR35: 8.7 | AS35: 9.7 | AT35: 10.4 | AU35: 10.8 | AV35: 11.4 | AW35: 11.9 | AX35: 13.8 | AY35: 12.7 | AZ35: 13.4 | BA35: 14.5 | BB35: 15.2 | BC35: 15.6 | BD35: 15.9 | BE35: 15.8 | BF35: 15.8 | BG35: 15.2 | BH35: 14.2 | BI35: 13.4 | BJ35: 12.3 | BK35: 11.2 | BL35: 11.4 | BM35: 11.8 | BN35: 9.8 | BO35: 8.2 | BP35: 7.5
A36: Transfer Payments | B36: n.a. | C36: Curr Transfers | D36: 0 | E36: 0 | F36: 0 | G36: 0 | H36: 0 | I36: 0 | J36: 0 | K36: 0 | L36: 0 | M36: 0 | N36: 0 | O36: 0 | P36: 0 | Q36: 0 | R36: 0 | S36: 0 | T36: 0 | U36: 0 | V36: 0 | W36: 0 | X36: 0 | Y36: 0 | Z36: 0 | AA36: 0 | AB36: 0 | AC36: 0 | AD36: 0 | AE36: 0 | AF36: 0 | AG36: 0 | AH36: 0 | AI36: 0 | AJ36: 0 | AK36: 0 | AL36: 0 | AM36: 0 | AN36: 0 | AO36: 0 | AP36: 0 | AQ36: 0 | AR36: 0 | AS36: 0 | AT36: 0 | AU36: 0 | AV36: 0 | AW36: 0 | AX36: 0 | AY36: 0 | AZ36: 0 | BA36: 0 | BB36: 0 | BC36: 0 | BD36: 0 | BE36: 0 | BF36: 0 | BG36: 0 | BH36: 0 | BI36: 0 | BJ36: 0 | BK36: 0 | BL36: 0 | BM36: 0 | BN36: 0 | BO36: 0 | BP36: 0
A37: Rental inc of persons for tenant-occupied housing owned by npishes | B37: T 7.9,14 | C37: Rental Inc w/ CCAdj | D37: 0 | E37: 0 | F37: 0 | G37: 0 | H37: 0 | I37: 0 | J37: 0 | K37: 0 | L37: 0 | M37: 0 | N37: 0 | O37: 0 | P37: 0 | Q37: 0 | R37: 0 | S37: 0 | T37: 0 | U37: 0 | V37: 0 | W37: 0 | X37: 0 | Y37: 0 | Z37: 0 | AA37: 0 | AB37: 0.1 | AC37: 0.2 | AD37: 0.1 | AE37: 0.1 | AF37: 0.1 | AG37: 0.1 | AH37: 0.2 | AI37: 0.2 | AJ37: 0.2 | AK37: 0.4 | AL37: 0.6 | AM37: 0.8 | AN37: 1 | AO37: 1 | AP37: 1.1 | AQ37: 1.1 | AR37: 1.1 | AS37: 1.1 | AT37: 1.1 | AU37: 1.2 | AV37: 1.3 | AW37: 1.6 | AX37: 1.7 | AY37: 2.1 | AZ37: 2.6 | BA37: 2.8 | BB37: 3.1 | BC37: 3.5 | BD37: 3.6 | BE37: 3.6 | BF37: 4 | BG37: 4.2 | BH37: 3.8 | BI37: 3.8 | BJ37: 3.6 | BK37: 3.8 | BL37: 4.6 | BM37: 5.3 | BN37: 6.3 | BO37: 6.8 | BP37: 7.6
A39: GVAgengov | B39: T 1.3.5, 8 | C39: GVAgengov | D39: 27.8 | E39: 27.2 | F39: 28.3 | G39: 28.6 | H39: 35.8 | I39: 40.4 | J39: 42.2 | K39: 43.5 | L39: 45.8 | M39: 49.1 | N39: 52.4 | O39: 55.8 | P39: 58.3 | Q39: 62 | R39: 66 | S39: 70.7 | T39: 75.5 | U39: 81.1 | V39: 86.6 | W39: 96.8 | X39: 107 | Y39: 118.8 | Z39: 130 | AA39: 143.5 | AB39: 156.4 | AC39: 169.4 | AD39: 183.2 | AE39: 201.3 | AF39: 224.5 | AG39: 243.5 | AH39: 264.6 | AI39: 287.5 | AJ39: 313 | AK39: 348.5 | AL39: 385.3 | AM39: 419 | AN39: 445.4 | AO39: 485.1 | AP39: 523.4 | AQ39: 556.3 | AR39: 591.5 | AS39: 630.6 | AT39: 672.2 | AU39: 722.7 | AV39: 767.6 | AW39: 801.9 | AX39: 831.2 | AY39: 859.9 | AZ39: 884.8 | BA39: 911.3 | BB39: 940.3 | BC39: 972.5 | BD39: 1021.6 | BE39: 1078.8 | BF39: 1139.6 | BG39: 1211.4 | BH39: 1292.2 | BI39: 1359.3 | BJ39: 1436.5 | BK39: 1512 | BL39: 1604.6 | BM39: 1698 | BN39: 1761.9 | BO39: 1811.7 | BP39: 1842.4
A40: Less: ECgengov | B40: T 6.2A-D, 77, 78, 88 + 80, 83, 93 in successive tables | C40: Less: ECgengov | D40: 17.643 | E40: 18.077 | F40: 20.121 | G40: 21.24 | H40: 27.741 | I40: 31.527 | J40: 32.409 | K40: 33.044 | L40: 34.796 | M40: 37.224 | N40: 39.783 | O40: 42.903 | P40: 44.861 | Q40: 48.074 | R40: 51.591 | S40: 55.454 | T40: 59.34 | U40: 64.408 | V40: 69.28 | W40: 78.419 | X40: 87.405 | Y40: 97.801 | Z40: 107.461 | AA40: 119.393 | AB40: 130.895 | AC40: 143.077 | AD40: 155.418 | AE40: 169.739 | AF40: 189.598 | AG40: 206.353 | AH40: 224.995 | AI40: 244.672 | AJ40: 266.104 | AK40: 295.502 | AL40: 325.184 | AM40: 352.719 | AN40: 375.28 | AO40: 410.428 | AP40: 443.689 | AQ40: 470.632 | AR40: 499.549 | AS40: 532.319 | AT40: 567.101 | AU40: 609.736 | AV40: 647.51 | AW40: 677.261 | AX40: 700.654 | AY40: 724.077 | AZ40: 743.537 | BA40: 766.762 | BB40: 792.176 | BC40: 820.664 | BD40: 863.055 | BE40: 911.96 | BF40: 967.138 | BG40: 1034.139 | BH40: 1109.423 | BI40: 1165.924 | BJ40: 1227.786 | BK40: 1287.273 | BL40: 1361.375 | BM40: 1438.386 | BN40: 1491.464 | BO40: 1533.51 | BP40: 1551.439
A41: Less: Tgengov | B41: n.a. | C41: Less: Tgengov
A42: GOSgengov | C42: GOSgengov | D42: 10.157 | E42: 9.123 | F42: 8.179 | G42: 7.36 | H42: 8.059 | I42: 8.873 | J42: 9.791 | K42: 10.456 | L42: 11.004 | M42: 11.876 | N42: 12.617 | O42: 12.897 | P42: 13.439 | Q42: 13.926 | R42: 14.409 | S42: 15.246 | T42: 16.16 | U42: 16.692 | V42: 17.32 | W42: 18.381 | X42: 19.595 | Y42: 20.999 | Z42: 22.539 | AA42: 24.107 | AB42: 25.505 | AC42: 26.323 | AD42: 27.782 | AE42: 31.561 | AF42: 34.902 | AG42: 37.147 | AH42: 39.605 | AI42: 42.828 | AJ42: 46.896 | AK42: 52.998 | AL42: 60.116 | AM42: 66.281 | AN42: 70.12 | AO42: 74.672 | AP42: 79.711 | AQ42: 85.668 | AR42: 91.951 | AS42: 98.281 | AT42: 105.099 | AU42: 112.964 | AV42: 120.09 | AW42: 124.639 | AX42: 130.546 | AY42: 135.823 | AZ42: 141.263 | BA42: 144.538 | BB42: 148.124 | BC42: 151.836 | BD42: 158.545 | BE42: 166.84 | BF42: 172.462 | BG42: 177.261 | BH42: 182.777 | BI42: 193.376 | BJ42: 208.714 | BK42: 224.727 | BL42: 243.225 | BM42: 259.614 | BN42: 270.436 | BO42: 278.19 | BP42: 290.961
A43: Less: CFCgengov | B43: T 7.5, 22 | C43: Less: CFCgengov | D43: 10.2 | E43: 9.1 | F43: 8.2 | G43: 7.4 | H43: 8 | I43: 8.9 | J43: 9.7 | K43: 10.4 | L43: 11 | M43: 11.9 | N43: 12.7 | O43: 12.9 | P43: 13.4 | Q43: 13.9 | R43: 14.4 | S43: 15.2 | T43: 16.1 | U43: 16.7 | V43: 17.4 | W43: 18.3 | X43: 19.6 | Y43: 21 | Z43: 22.5 | AA43: 24.1 | AB43: 25.5 | AC43: 26.3 | AD43: 27.8 | AE43: 31.6 | AF43: 34.9 | AG43: 37.1 | AH43: 39.6 | AI43: 42.8 | AJ43: 46.9 | AK43: 53 | AL43: 60.1 | AM43: 66.2 | AN43: 70.1 | AO43: 74.7 | AP43: 79.7 | AQ43: 85.6 | AR43: 92 | AS43: 98.3 | AT43: 105.1 | AU43: 112.9 | AV43: 120.1 | AW43: 124.7 | AX43: 130.5 | AY43: 135.8 | AZ43: 141.2 | BA43: 144.5 | BB43: 148.1 | BC43: 151.9 | BD43: 158.5 | BE43: 166.8 | BF43: 172.5 | BG43: 177.3 | BH43: 182.8 | BI43: 193.4 | BJ43: 208.7 | BK43: 224.7 | BL43: 243.2 | BM43: 259.6 | BN43: 270.4 | BO43: 278.2 | BP43: 291
...

Sheet Appndx 6.8.II.1
A18: Description | B18: Source | C18: Variable | D18: 1925 | E18: 1926 | F18: 1927 | G18: 1928 | H18: 1929 | I18: 1930 | J18: 1931 | K18: 1932 | L18: 1933 | M18: 1934 | N18: 1935 | O18: 1936 | P18: 1937 | Q18: 1938 | R18: 1939 | S18: 1940 | T18: 1941 | U18: 1942 | V18: 1943 | W18: 1944 | X18: 1945 | Y18: 1946 | Z18: 1947 | AA18: 1948 | AB18: 1949 | AC18: 1950 | AD18: 1951 | AE18: 1952 | AF18: 1953 | AG18: 1954 | AH18: 1955 | AI18: 1956 | AJ18: 1957 | AK18: 1958 | AL18: 1959 | AM18: 1960 | AN18: 1961 | AO18: 1962 | AP18: 1963 | AQ18: 1964 | AR18: 1965 | AS18: 1966 | AT18: 1967 | AU18: 1968 | AV18: 1969 | AW18: 1970 | AX18: 1971 | AY18: 1972 | AZ18: 1973 | BA18: 1974 | BB18: 1975 | BC18: 1976 | BD18: 1977 | BE18: 1978 | BF18: 1979 | BG18: 1980 | BH18: 1981 | BI18: 1982 | BJ18: 1983 | BK18: 1984 | BL18: 1985 | BM18: 1986 | BN18: 1987 | BO18: 1988 | BP18: 1989 | BQ18: 1990 | BR18: 1991 | BS18: 1992 | BT18: 1993 | BU18: 1994 | BV18: 1995 | BW18: 1996 | BX18: 1997 | BY18: 1998 | BZ18: 1999 | CA18: 2000 | CB18: 2001 | CC18: 2002 | CD18: 2003 | CE18: 2004 | CF18: 2005 | CG18: 2006 | CH18: 2007 | CI18: 2008 | CJ18: 2009 | CK18: 2010 | CL18: 2011 | CM18: 2012 | CN18: 2013
A19: BEA Current-Cost Corporate Net Stock | B19: FA Table 6.1, line 2: Bill-$ | C19: KNCcorpbea | D19: 98.1 | E19: 101 | F19: 102.4 | G19: 104.7 | H19: 103.6 | I19: 98.5 | J19: 88.4 | K19: 82.4 | L19: 83.2 | M19: 84.2 | N19: 83.7 | O19: 92 | P19: 95.2 | Q19: 93.9 | R19: 94.4 | S19: 100.1 | T19: 112.1 | U19: 118.9 | V19: 119.3 | W19: 120.2 | X19: 131.2 | Y19: 159.4 | Z19: 190.1 | AA19: 208.1 | AB19: 212.2 | AC19: 238.1 | AD19: 258.5 | AE19: 273.5 | AF19: 287 | AG19: 295.3 | AH19: 325 | AI19: 360.7 | AJ19: 386.9 | AK19: 394.4 | AL19: 411.6 | AM19: 419.9 | AN19: 430.3 | AO19: 444.2 | AP19: 458.3 | AQ19: 483.9 | AR19: 517.4 | AS19: 563.4 | AT19: 610.8 | AU19: 672.6 | AV19: 741.1 | AW19: 815.7 | AX19: 895.2 | AY19: 972.2 | AZ19: 1097.4 | BA19: 1346.4 | BB19: 1495.4 | BC19: 1643.8 | BD19: 1829.9 | BE19: 2081.5 | BF19: 2399.7 | BG19: 2761.2 | BH19: 3125.3 | BI19: 3318.6 | BJ19: 3415.3 | BK19: 3618.4 | BL19: 3819.3 | BM19: 3989.7 | BN19: 4197.6 | BO19: 4462.9 | BP19: 4728.2 | BQ19: 4993.1 | BR19: 5105.1 | BS19: 5275.6 | BT19: 5523.9 | BU19: 5823.9 | BV19: 6154.2 | BW19: 6469.9 | BX19: 6830.5 | BY19: 7217.6 | BZ19: 7641.6 | CA19: 8175.4 | CB19: 8595.6 | CC19: 8907.7 | CD19: 9185.8 | CE19: 9909.5 | CF19: 10768.3 | CG19: 11679.9 | CH19: 12317.8 | CI19: 13138 | CJ19: 12701.7 | CK19: 12994.6 | CL19: 13530.8
A20: BEA Chain-Index Real Corporate Net Stock | B20: FA Table 6.2, line 2: 2005 = 100 | C20: KNRIndxcorpbea | D20: 13.038 | E20: 13.38 | F20: 13.649 | G20: 13.929 | H20: 14.298 | I20: 14.519 | J20: 14.442 | K20: 14.169 | L20: 13.891 | M20: 13.703 | N20: 13.579 | O20: 13.607 | P20: 13.752 | Q20: 13.695 | R20: 13.694 | S20: 13.827 | T20: 14.044 | U20: 13.978 | V20: 13.817 | W20: 13.797 | X20: 14.013 | Y20: 14.532 | Z20: 15.105 | AA20: 15.675 | AB20: 16.051 | AC20: 16.481 | AD20: 17.015 | AE20: 17.551 | AF20: 18.15 | AG20: 18.649 | AH20: 19.238 | AI20: 19.98 | AJ20: 20.719 | AK20: 21.123 | AL20: 21.598 | AM20: 22.218 | AN20: 22.777 | AO20: 23.452 | AP20: 24.158 | AQ20: 25.076 | AR20: 26.327 | AS20: 27.856 | AT20: 29.223 | AU20: 30.643 | AV20: 32.161 | AW20: 33.48 | AX20: 34.66 | AY20: 36.02 | AZ20: 37.719 | BA20: 39.393 | BB20: 40.499 | BC20: 41.65 | BD20: 43.089 | BE20: 44.985 | BF20: 47.115 | BG20: 49.079 | BH20: 51.06 | BI20: 52.574 | BJ20: 53.889 | BK20: 55.932 | BL20: 58.089 | BM20: 59.785 | BN20: 61.217 | BO20: 62.708 | BP20: 64.332 | BQ20: 66.06 | BR20: 67.245 | BS20: 68.413 | BT20: 69.996 | BU20: 71.864 | BV20: 74.257 | BW20: 77.004 | BX20: 80.052 | BY20: 83.471 | BZ20: 87.15 | CA20: 91.139 | CB20: 93.913 | CC20: 95.374 | CD20: 96.682 | CE20: 98.214 | CF20: 100 | CG20: 102.48 | CH20: 105.241 | CI20: 107.527 | CJ20: 107.696 | CK20: 108.012 | CL20: 108.992
A21: BEA Constant-Cost Corporate Net Stock | B21: KNRIndex(t)*KNC(2005)/100: Bills-2005$ | C21: KNRcorpbea | D21: =D20*$CF$19/100 -> 1403.971 | E21: =E20*$CF$19/100 -> 1440.7985 | F21: =F20*$CF$19/100 -> 1469.7653 | G21: =G20*$CF$19/100 -> 1499.9165 | H21: =H20*$CF$19/100 -> 1539.6515 | I21: =I20*$CF$19/100 -> 1563.4495 | J21: =J20*$CF$19/100 -> 1555.1579 | K21: =K20*$CF$19/100 -> 1525.7604 | ... CL21: =CL20*$CF$19/100 -> 11736.586
A22: Implicit Price Deflator, Net Corporate Capital Stock | B22: (KNCcorp/KNRcorp)*100 | C22: pKN | D22: =(D19/D21)*100 -> 6.987324 | E22: =(E19/E21)*100 -> 7.0100016 | F22: =(F19/F21)*100 -> 6.9670989 | G22: =(G19/G21)*100 -> 6.9803885 | H22: =(H19/H21)*100 -> 6.7287953 | I22: =(I19/I21)*100 -> 6.3001716 | J22: =(J19/J21)*100 -> 5.6843103 | K22: =(K19/K21)*100 -> 5.4005857 | ... CL22: =(CL19/CL21)*100 -> 115.28736
A23: BEA Historical-Cost Corporate Net Stock | B23: FA Table 6.3, line 2: Bill-$ | C23: KNHcorpbea | D23: 69.2 | E23: 72.3 | F23: 74.9 | G23: 77.5 | H23: 80.9 | I23: 82.7 | J23: 82.3 | K23: 80.4 | L23: 78.6 | M23: 77.4 | N23: 76.7 | O23: 77 | P23: 78.5 | Q23: 78.6 | R23: 79 | S23: 80.5 | T23: 83 | U23: 83.7 | V23: 83.8 | W23: 85.1 | X23: 88.5 | Y23: 95.3 | Z23: 105 | AA23: 115.9 | AB23: 124.4 | AC23: 133.7 | AD23: 146 | AE23: 158.6 | AF23: 172.3 | AG23: 184.4 | AH23: 197.9 | AI23: 216 | AJ23: 235.4 | AK23: 248.7 | AL23: 263.6 | AM23: 280.9 | AN23: 296.5 | AO23: 313.9 | AP23: 331.7 | AQ23: 353.5 | AR23: 382.1 | AS23: 417.3 | AT23: 450.7 | AU23: 487.4 | AV23: 529 | AW23: 569.4 | AX23: 609.7 | AY23: 657.3 | AZ23: 718.2 | BA23: 790.1 | BB23: 858.5 | BC23: 934.6 | BD23: 1030.7 | BE23: 1156.7 | BF23: 1310.3 | BG23: 1474.4 | BH23: 1662.3 | BI23: 1834.5 | BJ23: 1987.1 | BK23: 2181.8 | BL23: 2383.8 | BM23: 2556.7 | BN23: 2712.7 | BO23: 2881.4 | BP23: 3067.8 | BQ23: 3267.3 | BR23: 3430.2 | BS23: 3587.9 | BT23: 3777.9 | BU23: 3995.7 | BV23: 4261.1 | BW23: 4553.3 | BX23: 4871 | BY23: 5215.3 | BZ23: 5585.3 | CA23: 5995.7 | CB23: 6306.5 | CC23: 6499.8 | CD23: 6684.5 | CE23: 6906.9 | CF23: 7201.1 | CG23: 7605.3 | CH23: 8068.8 | CI23: 8508.3 | CJ23: 8673.5 | CK23: 8848.6 | CL23: 9122.4
A25: Current-Cost Corporate Depreciation | B25: FA Table 6.4, line 2: Bill-$ | C25: DEPCcorp | D25: 4.5 | E25: 4.7 | F25: 4.8 | G25: 4.9 | H25: 5 | I25: 4.8 | J25: 4.5 | K25: 4 | L25: 3.8 | M25: 3.9 | N25: 3.9 | O25: 4 | P25: 4.4 | Q25: 4.5 | R25: 4.5 | S25: 4.6 | T25: 5.1 | U25: 5.8 | V25: 5.8 | W25: 6 | X25: 6.1 | Y25: 6.9 | Z25: 8.9 | AA25: 10.4 | AB25: 11.2 | AC25: 12 | AD25: 13.6 | AE25: 14.5 | AF25: 15.4 | AG25: 16.2 | AH25: 17.1 | AI25: 19.2 | AJ25: 21.3 | AK25: 22.7 | AL25: 23.7 | AM25: 24 | AN25: 24.7 | AO25: 25.6 | AP25: 26.7 | AQ25: 28.2 | AR25: 30.5 | AS25: 33.5 | AT25: 36.9 | AU25: 40.7 | AV25: 45.2 | AW25: 50.1 | AX25: 54.9 | AY25: 59.8 | AZ25: 67 | BA25: 78.9 | BB25: 94.5 | BC25: 104.7 | BD25: 118.1 | BE25: 134.4 | BF25: 155.3 | BG25: 180 | BH25: 208.3 | BI25: 231.6 | BJ25: 240.7 | BK25: 253.2 | BL25: 272 | BM25: 290.1 | BN25: 306.7 | BO25: 329.1 | BP25: 351.1 | BQ25: 373.4 | BR25: 392.4 | BS25: 402.3 | BT25: 420.4 | BU25: 445.2 | BV25: 477.2 | BW25: 506.3 | BX25: 541.2 | BY25: 578.6 | BZ25: 624.9 | CA25: 682.1 | CB25: 725.1 | CC25: 749.3 | CD25: 768.3 | CE25: 803.1 | CF25: 855.8 | CG25: 918.4 | CH25: 976.4 | CI25: 1028.5 | CJ25: 1030.4 | CK25: 1026.5 | CL25: 1061.9
A26: Correct Depreciation Rate | B26: DEPcorp/[(pKN/100)*KNR(-1)] | C26: dcorpstar | E26: =(E25/(E22*D21/100)) -> 0.047755305 | F26: =(F25/(F22*E21/100)) -> 0.047817405 | G26: =(G25/(G22*F21/100)) -> 0.04776046 | H26: =(H25/(H22*G21/100)) -> 0.049541095 | I26: =(I25/(I22*H21/100)) -> 0.049484185 | J26: =(J25/(J22*I21/100)) -> 0.050635008 | K26: =(K25/(K22*J21/100)) -> 0.047626058 | L26: =(L25/(L22*K21/100)) -> 0.044776958 | ... CL26: =(CL25/(CL22*CK21/100)) -> 0.079192264
A27: Historical-Cost Corporate Depreciation | B27: FA Table 6.6, line 2: Bill-$ | C27: DEPHcorpbea | D27: 4 | E27: 4.2 | F27: 4.3 | G27: 4.3 | H27: 4.4 | I27: 4.5 | J27: 4.4 | K27: 4.2 | L27: 4 | M27: 3.9 | N27: 3.8 | O27: 3.8 | P27: 4 | Q27: 4 | R27: 4 | S27: 4.1 | T27: 4.3 | U27: 4.4 | V27: 4.4 | W27: 4.5 | X27: 4.7 | Y27: 5.2 | Z27: 6 | AA27: 6.9 | AB27: 7.7 | AC27: 8.5 | AD27: 9.3 | AE27: 10.1 | AF27: 11.1 | AG27: 12.1 | AH27: 13 | AI27: 14.2 | AJ27: 15.5 | AK27: 17 | AL27: 17.8 | AM27: 18.5 | AN27: 19.6 | AO27: 20.8 | AP27: 22.2 | AQ27: 23.8 | AR27: 26 | AS27: 28.7 | AT27: 31.5 | AU27: 34.4 | AV27: 37.7 | AW27: 41.1 | AX27: 44.3 | AY27: 48.3 | AZ27: 53.8 | BA27: 59.7 | BB27: 65.7 | BC27: 72.4 | BD27: 81.2 | BE27: 92.3 | BF27: 105.8 | BG27: 120.5 | BH27: 136.6 | BI27: 154.8 | BJ27: 171 | BK27: 188.9 | BL27: 210.6 | BM27: 229.4 | BN27: 247.3 | BO27: 264.5 | BP27: 283.3 | BQ27: 302.6 | BR27: 319.5 | BS27: 334.8 | BT27: 354.2 | BU27: 379.1 | BV27: 408.8 | BW27: 443 | BX27: 482.4 | BY27: 526.7 | BZ27: 575.3 | CA27: 627.4 | CB27: 668.7 | CC27: 691.8 | CD27: 707.1 | CE27: 727.9 | CF27: 754.4 | CG27: 788.7 | CH27: 831.9 | CI27: 868.3 | CJ27: 884.7 | CK27: 888.7 | CL27: 908.6
A28: Current-Cost Gross Investment | B28: FA Table 6.7, line 2: Bill-$ | C28: IGCcorpbea | D28: 7.3 | E28: 7.3 | F28: 6.9 | G28: 7 | H28: 7.7 | I28: 6.4 | J28: 4 | K28: 2.4 | L28: 2.2 | M28: 2.7 | N28: 3.2 | O28: 4.1 | P28: 5.4 | Q28: 4.1 | R28: 4.4 | S28: 5.6 | T28: 6.8 | U28: 5.2 | V28: 4.5 | W28: 5.8 | X28: 8.1 | Y28: 12 | Z28: 15.7 | AA28: 17.8 | AB28: 16.2 | AC28: 17.8 | AD28: 21.7 | AE28: 22.7 | AF28: 24.8 | AG28: 24.1 | AH28: 26.6 | AI28: 32.2 | AJ28: 34.9 | AK28: 30.2 | AL28: 32.7 | AM28: 35.6 | AN28: 35.2 | AO28: 38.3 | AP28: 40.4 | AQ28: 46.1 | AR28: 55.1 | AS28: 63.8 | AT28: 64.9 | AU28: 71 | AV28: 79.2 | AW28: 81.4 | AX28: 84.6 | AY28: 96.2 | AZ28: 114.8 | BA28: 131.2 | BB28: 134 | BC28: 148.6 | BD28: 177.4 | BE28: 218.2 | BF28: 259.5 | BG28: 284.6 | BH28: 324.4 | BI28: 327.1 | BJ28: 323.7 | BK28: 383.6 | BL28: 412.5 | BM28: 402.3 | BN28: 403.3 | BO28: 433.2 | BP28: 471.5 | BQ28: 502.1 | BR28: 482.4 | BS28: 495.3 | BT28: 545.4 | BU28: 600.7 | BV28: 674.8 | BW28: 735.2 | BX28: 800 | BY28: 871 | BZ28: 946.3 | CA28: 1037.8 | CB28: 991.7 | CC28: 885.1 | CD28: 891.8 | CE28: 960 | CF28: 1065.2 | CG28: 1193 | CH28: 1295.3 | CI28: 1311.5 | CJ28: 1049.8 | CK28: 1063.9 | CL28: 1182.4 | CM28: =CL28*(1585.5/1456.2) -> 1287.3885 | CN28: =CM28*(1656.6/1585.5) -> 1345.1201
A29: Chain-Type Quantity Index Gross Investment | B29: FA Table 6.8, line 2: Bill-$ | C29: IGRcorpindexbea | D29: 4.341 | E29: 4.369 | F29: 4.1 | G29: 4.202 | H29: 4.686 | I29: 4.075 | J29: 2.74 | K29: 1.776 | L29: 1.663 | M29: 2.008 | N29: 2.29 | O29: 3.006 | P29: 3.627 | Q29: 2.719 | R29: 2.979 | S29: 3.652 | T29: 4.138 | U29: 2.87 | V29: 2.375 | W29: 2.999 | X29: 4.106 | Y29: 5.658 | Z29: 6.328 | AA29: 6.593 | AB29: 5.828 | AC29: 6.25 | AD29: 6.927 | AE29: 7.097 | AF29: 7.616 | AG29: 7.356 | AH29: 8.027 | AI29: 9.022 | AJ29: 9.256 | AK29: 7.931 | AL29: 8.389 | AM29: 9.133 | AN29: 9.064 | AO29: 9.884 | AP29: 10.409 | AQ29: 11.802 | AR29: 13.97 | AS29: 15.96 | AT29: 15.875 | AU29: 16.812 | AV29: 18.042 | AW29: 17.712 | AX29: 17.616 | AY29: 19.429 | AZ29: 22.275 | BA29: 23.143 | BB29: 20.797 | BC29: 21.824 | BD29: 24.452 | BE29: 28.338 | BF29: 31.235 | BG29: 31.592 | BH29: 32.878 | BI29: 31.439 | BJ29: 31.457 | BK29: 37.465 | BL29: 40.149 | BM29: 38.793 | BN29: 38.662 | BO29: 40.552 | BP29: 43.32 | BQ29: 45.39 | BR29: 43.07 | BS29: 44.665 | BT29: 49.201 | BU29: 54.004 | BV29: 60.449 | BW29: 66.938 | BX29: 74.089 | BY29: 82.811 | BZ29: 91.39 | CA29: 100.294 | CB29: 96.265 | CC29: 86.285 | CD29: 87.116 | CE29: 92.709 | CF29: 100 | CG29: 108.115 | CH29: 115.008 | CI29: 114.026 | CJ29: 92.515 | CK29: 94.233 | CL29: 102.621 | CM29: =CL29*(120.696/112.46) -> 110.13644 | CN29: =CM29*(124.708/120.696) -> 113.79744
A30: Constant-Cost Quantity Index Gross Investment | B30: (IGRcorpindexbea(t)/100)*IGCcorpbea(2005): Bills-2005$ | C30: IGRcorpbea | D30: =(D29/100)*$CF$28 -> 46.240332 | E30: =(E29/100)*$CF$28 -> 46.538588 | F30: =(F29/100)*$CF$28 -> 43.6732 | G30: =(G29/100)*$CF$28 -> 44.759704 | H30: =(H29/100)*$CF$28 -> 49.915272 | I30: =(I29/100)*$CF$28 -> 43.4069 | J30: =(J29/100)*$CF$28 -> 29.18648 | K30: =(K29/100)*$CF$28 -> 18.917952 | ... CN30: =(CN29/100)*$CF$28 -> 1212.1703
A31: Implicit Price Deflator, Gross Investment | B31: (IGCcorpbea/IGRcorpbea)*100 | C31: pIGcorpbea | D31: =(D28/D30)*100 -> 15.787084 | E31: =(E28/E30)*100 -> 15.685908 | F31: =(F28/F30)*100 -> 15.799163 | G31: =(G28/G30)*100 -> 15.639067 | H31: =(H28/H30)*100 -> 15.426141 | I31: =(I28/I30)*100 -> 14.7442 | J31: =(J28/J30)*100 -> 13.704976 | K31: =(K28/K30)*100 -> 12.686363 | ... CN31: =(CN28/CN30)*100 -> 110.96791
A33: Current-cost approximation using Ch 6 eq. 6.57 | B33: KNC' = IGC + (1-d)*(pKN/pKN(-1))*KNC'(-1) | C33: KNCcorp' | D33: =D19 -> 98.1 | E33: =E28+(1-E26)*(E22/D22)*D33 -> 101.01839 | F33: =F28+(1-F26)*(F22/E22)*E33 -> 102.49926 | G33: =G28+(1-G26)*(G22/F22)*F33 -> 104.79002 | H33: =H28+(1-H26)*(H22/G22)*G33 -> 103.70879 | I33: =I28+(1-I26)*(I22/H22)*H33 -> 98.69751 | J33: =J28+(1-J26)*(J22/I22)*I33 -> 88.5405 | K33: =K28+(1-K26)*(K22/J22)*J33 -> 82.514764 | L33: =L28+(1-L26)*(L22/K22)*K33 -> 83.377983 | ... CL33: =CL28+(1-CL26)*(CL22/CK22)*CK33 -> 13531.22
A34: Constant-cost approximation using Ch 6 eq. 6.58 | B34: KNR' = (IGC*100/pKN) + (1-d)*KNR'(-1) | C34: KNRcorp' | D34: =D21 -> 1403.971 | E34: =(E28*100/E22)+(1-E26)*D34 -> 1441.0608 | F34: =(F28*100/F22)+(1-F26)*E34 -> 1471.1899 | G34: =(G28*100/G22)+(1-G26)*F34 -> 1501.2062 | H34: =(H28*100/H22)+(1-H26)*G34 -> 1541.2683 | I34: =(I28*100/I22)+(1-I26)*H34 -> 1566.5845 | J34: =(J28*100/J22)+(1-J26)*I34 -> 1557.6296 | K34: =(K28*100/K22)+(1-K26)*J34 -> 1527.8855 | L34: =(L28*100/L22)+(1-L26)*K34 -> 1499.0245 | ... CL34: =(CL28*100/CL22)+(1-CL26)*CK34 -> 11736.949
A35: Historical-cost approximation using Ch 6 eq. 6.59 | B35: KNH = INH + KNH(-1) where INH = IGC - DEPH, DEPH = hist cost deprec | C35: KNHcorp' | D35: =D23 -> 69.2 | E35: =(E28-E27)+D35 -> 72.3 | F35: =(F28-F27)+E35 -> 74.9 | G35: =(G28-G27)+F35 -> 77.6 | H35: =(H28-H27)+G35 -> 80.9 | I35: =(I28-I27)+H35 -> 82.8 | J35: =(J28-J27)+I35 -> 82.4 | K35: =(K28-K27)+J35 -> 80.6 | L35: =(L28-L27)+K35 -> 78.8 | ... CL35: =(CL28-CL27)+CK35 -> 9176.9
A37: Whelan-Liu Depreciation Rate | B37: Depcorp/KNCcorpbea(-1) | C37: dcorpWhelanLiu | E37: =E25/D19 -> 0.047910296 | F37: =F25/E19 -> 0.047524752 | G37: =G25/F19 -> 0.047851562 | H37: =H25/G19 -> 0.047755492 | I37: =I25/H19 -> 0.046332046 | J37: =J25/I19 -> 0.045685279 | K37: =K25/J19 -> 0.045248869 | L37: =L25/K19 -> 0.046116505 | ... CL37: =CL25/CK19 -> 0.08171856
A39: Relative Current-Cost Approximation | B39: KNCcorp'/KNCcorp | C39: KNCcorp'ratio | D39: =D33/D19 -> 1 | E39: =E33/E19 -> 1.000182 | F39: =F33/F19 -> 1.0009693 | G39: =G33/G19 -> 1.0008598 | H39: =H33/H19 -> 1.0010501 | I39: =I33/I19 -> 1.0020052 | J39: =J33/J19 -> 1.0015894 | K39: =K33/K19 -> 1.0013928 | ... CL39: =CL33/CL19 -> 1.000031
A40: Relative Constant-Cost Approximation | B40: KNRcorp'/KNRcorp | C40: KNRcorp'ratio | D40: =D34/D21 -> 1 | E40: =E34/E21 -> 1.000182 | F40: =F34/F21 -> 1.0009693 | G40: =G34/G21 -> 1.0008598 | H40: =H34/H21 -> 1.0010501 | I40: =I34/I21 -> 1.0020052 | J40: =J34/J21 -> 1.0015894 | K40: =K34/K21 -> 1.0013928 | ... CL40: =CL34/CL21 -> 1.000031
A41: Relative Historical-Cost Approximation | B41: KNHcorp'/KNhcorp | C41: KNHcorp'ratio | D41: =D35/D23 -> 1 | E41: =E35/E23 -> 1 | F41: =F35/F23 -> 1 | G41: =G35/G23 -> 1.0012903 | H41: =H35/H23 -> 1 | I41: =I35/I23 -> 1.0012092 | J41: =J35/J23 -> 1.0012151 | K41: =K35/K23 -> 1.0024876 | ... CL41: =CL35/CL23 -> 1.0059743
B43: Average Accuracy of GPIM rules, 1947-2009
A44: Average KNCcorpratio | B44: =AVERAGE(D39:CL39) -> 0.99612784
A45: Average KNRcorpratio | B45: =AVERAGE(D40:CL40) -> 0.99612784
A46: Average KNHcorpratio | B46: =AVERAGE(D41:CL41) -> 1.0022797

Sheet Appndx 6.8.II.2
A8: All estimates pertain to Corporate Current-Cost Net Stocks (IGC, d, and pKN are taken from Appendix 6.8B1)
A9: Appendix 7.2C2: Effects of Different Initial Values
A10: Description | B10: Source | C10: Variable | D10: 1925 | E10: 1926 | F10: 1927 | G10: 1928 | H10: 1929 | I10: 1930 | J10: 1931 | K10: 1932 | L10: 1933 | M10: 1934 | N10: 1935 | O10: 1936 | P10: 1937 | Q10: 1938 | R10: 1939 | S10: 1940 | T10: 1941 | U10: 1942 | V10: 1943 | W10: 1944 | X10: 1945 | Y10: 1946 | Z10: 1947 | AA10: 1948 | AB10: 1949 | AC10: 1950 | AD10: 1951 | AE10: 1952 | AF10: 1953 | AG10: 1954 | AH10: 1955 | AI10: 1956 | AJ10: 1957 | AK10: 1958 | AL10: 1959 | AM10: 1960 | AN10: 1961 | AO10: 1962 | AP10: 1963 | AQ10: 1964 | AR10: 1965 | AS10: 1966 | AT10: 1967 | AU10: 1968 | AV10: 1969 | AW10: 1970 | AX10: 1971 | AY10: 1972 | AZ10: 1973 | BA10: 1974 | BB10: 1975 | BC10: 1976 | BD10: 1977 | BE10: 1978 | BF10: 1979 | BG10: 1980 | BH10: 1981 | BI10: 1982 | BJ10: 1983 | BK10: 1984 | BL10: 1985 | BM10: 1986 | BN10: 1987 | BO10: 1988 | BP10: 1989 | BQ10: 1990 | BR10: 1991 | BS10: 1992 | BT10: 1993 | BU10: 1994 | BV10: 1995 | BW10: 1996 | BX10: 1997 | BY10: 1998 | BZ10: 1999 | CA10: 2000 | CB10: 2001 | CC10: 2002 | CD10: 2003 | CE10: 2004 | CF10: 2005 | CG10: 2006 | CH10: 2007 | CI10: 2008 | CJ10: 2009 | CK10: 2010 | CL10: 2011
A11: KNC' = IGC + (1-d)*(pKN/pKN(-1))*KNC'(-1)
A12: BEA 2011 initial value | B12: FA Table 6.1, line 1 | C12: KNCcorpbea | D12: 98.1 | E12: ='Appndx 6.8.II.1'!E28+(1-'Appndx 6.8.II.1'!E26)*('Appndx 6.8.II.1'!E22/'Appndx 6.8.II.1'!D22)*'Appndx 6.8.II.2'!D12 -> 101.01839 | F12: ='Appndx 6.8.II.1'!F28+(1-'Appndx 6.8.II.1'!F26)*('Appndx 6.8.II.1'!F22/'Appndx 6.8.II.1'!E22)*'Appndx 6.8.II.2'!E12 -> 102.49926 | G12: ='Appndx 6.8.II.1'!G28+(1-'Appndx 6.8.II.1'!G26)*('Appndx 6.8.II.1'!G22/'Appndx 6.8.II.1'!F22)*'Appndx 6.8.II.2'!F12 -> 104.79002 | H12: ='Appndx 6.8.II.1'!H28+(1-'Appndx 6.8.II.1'!H26)*('Appndx 6.8.II.1'!H22/'Appndx 6.8.II.1'!G22)*'Appndx 6.8.II.2'!G12 -> 103.70879 | I12: ='Appndx 6.8.II.1'!I28+(1-'Appndx 6.8.II.1'!I26)*('Appndx 6.8.II.1'!I22/'Appndx 6.8.II.1'!H22)*'Appndx 6.8.II.2'!H12 -> 98.69751 | J12: ='Appndx 6.8.II.1'!J28+(1-'Appndx 6.8.II.1'!J26)*('Appndx 6.8.II.1'!J22/'Appndx 6.8.II.1'!I22)*'Appndx 6.8.II.2'!I12 -> 88.5405 | K12: ='Appndx 6.8.II.1'!K28+(1-'Appndx 6.8.II.1'!K26)*('Appndx 6.8.II.1'!K22/'Appndx 6.8.II.1'!J22)*'Appndx 6.8.II.2'!J12 -> 82.514764 | L12: ='Appndx 6.8.II.1'!L28+(1-'Appndx 6.8.II.1'!L26)*('Appndx 6.8.II.1'!L22/'Appndx 6.8.II.1'!K22)*'Appndx 6.8.II.2'!K12 -> 83.377983 | ... CL12: ='Appndx 6.8.II.1'!CL28+(1-'Appndx 6.8.II.1'!CL26)*('Appndx 6.8.II.1'!CL22/'Appndx 6.8.II.1'!CK22)*'Appndx 6.8.II.2'!CK12 -> 13531.22
A13: BEA 1993 initial value | B13: Table A.13, p. 294 | C13: KNCcorp1' | D13: 77.769 | E13: ='Appndx 6.8.II.1'!E28+(1-'Appndx 6.8.II.1'!E26)*('Appndx 6.8.II.1'!E22/'Appndx 6.8.II.1'!D22)*D13 -> 81.595465 | F13: ='Appndx 6.8.II.1'!F28+(1-'Appndx 6.8.II.1'!F26)*('Appndx 6.8.II.1'!F22/'Appndx 6.8.II.1'!E22)*E13 -> 84.11828 | G13: ='Appndx 6.8.II.1'!G28+(1-'Appndx 6.8.II.1'!G26)*('Appndx 6.8.II.1'!G22/'Appndx 6.8.II.1'!F22)*F13 -> 87.253543 | H13: ='Appndx 6.8.II.1'!H28+(1-'Appndx 6.8.II.1'!H26)*('Appndx 6.8.II.1'!H22/'Appndx 6.8.II.1'!G22)*G13 -> 87.641839 | I13: ='Appndx 6.8.II.1'!I28+(1-'Appndx 6.8.II.1'!I26)*('Appndx 6.8.II.1'!I22/'Appndx 6.8.II.1'!H22)*H13 -> 84.398436 | J13: ='Appndx 6.8.II.1'!J28+(1-'Appndx 6.8.II.1'!J26)*('Appndx 6.8.II.1'!J22/'Appndx 6.8.II.1'!I22)*I13 -> 76.292461 | K13: ='Appndx 6.8.II.1'!K28+(1-'Appndx 6.8.II.1'!K26)*('Appndx 6.8.II.1'!K22/'Appndx 6.8.II.1'!J22)*J13 -> 71.43228 | L13: ='Appndx 6.8.II.1'!L28+(1-'Appndx 6.8.II.1'!L26)*('Appndx 6.8.II.1'!L22/'Appndx 6.8.II.1'!K22)*K13 -> 72.47504 | ... CL13: ='Appndx 6.8.II.1'!CL28+(1-'Appndx 6.8.II.1'!CL26)*('Appndx 6.8.II.1'!CL22/'Appndx 6.8.II.1'!CK22)*CK13 -> 13530.074
A14: SCB 1985 initial value | B14: Table 6, p. 56 | C14: KNCcorp2' | D14: 67.1 | E14: ='Appndx 6.8.II.1'!E28+(1-'Appndx 6.8.II.1'!E26)*('Appndx 6.8.II.1'!E22/'Appndx 6.8.II.1'!D22)*D14 -> 71.402994 | F14: ='Appndx 6.8.II.1'!F28+(1-'Appndx 6.8.II.1'!F26)*('Appndx 6.8.II.1'!F22/'Appndx 6.8.II.1'!E22)*E14 -> 74.472583 | G14: ='Appndx 6.8.II.1'!G28+(1-'Appndx 6.8.II.1'!G26)*('Appndx 6.8.II.1'!G22/'Appndx 6.8.II.1'!F22)*F14 -> 78.051009 | H14: ='Appndx 6.8.II.1'!H28+(1-'Appndx 6.8.II.1'!H26)*('Appndx 6.8.II.1'!H22/'Appndx 6.8.II.1'!G22)*G14 -> 79.210462 | I14: ='Appndx 6.8.II.1'!I28+(1-'Appndx 6.8.II.1'!I26)*('Appndx 6.8.II.1'!I22/'Appndx 6.8.II.1'!H22)*H14 -> 76.89478 | J14: ='Appndx 6.8.II.1'!J28+(1-'Appndx 6.8.II.1'!J26)*('Appndx 6.8.II.1'!J22/'Appndx 6.8.II.1'!I22)*I14 -> 69.865117 | K14: ='Appndx 6.8.II.1'!K28+(1-'Appndx 6.8.II.1'!K26)*('Appndx 6.8.II.1'!K22/'Appndx 6.8.II.1'!J22)*J14 -> 65.616578 | L14: ='Appndx 6.8.II.1'!L28+(1-'Appndx 6.8.II.1'!L26)*('Appndx 6.8.II.1'!L22/'Appndx 6.8.II.1'!K22)*K14 -> 66.753556 | ... CL14: ='Appndx 6.8.II.1'!CL28+(1-'Appndx 6.8.II.1'!CL26)*('Appndx 6.8.II.1'!CL22/'Appndx 6.8.II.1'!CK22)*CK14 -> 13529.472
A16: Ratio KNCcorp1' to KNCcorpbea | B16: KNCcorp1'/KNCcorpbea | C16: KNCcorp1'ratio | D16: =D13/D12 -> 0.79275229 | E16: =E13/E12 -> 0.80772886 | F16: =F13/F12 -> 0.82067208 | G16: =G13/G12 -> 0.83265123 | H16: =H13/H12 -> 0.84507627 | I16: =I13/I12 -> 0.85512223 | J16: =J13/J12 -> 0.86166739 | K16: =K13/K12 -> 0.86569089 | ... CL16: =CL13/CL12 -> 0.9999153
A17: Ratio KNCcorp2' to KNCcorpbea | B17: KNCCorp2'/KNCorpbea | C17: KNCCorp2'ratio | D17: =D14/D12 -> 0.68399592 | E17: =E14/E12 -> 0.70683166 | F17: =F14/F12 -> 0.72656704 | G17: =G14/G12 -> 0.74483243 | H17: =H14/H12 -> 0.76377769 | I17: =I14/I12 -> 0.77909543 | J17: =J14/J12 -> 0.78907525 | K17: =K14/K12 -> 0.79521015 | ... CL17: =CL14/CL12 -> 0.99987086

Sheet Appndx 6.8.II.3
A27: New Net Stock Calculations using BEA 1993 depreciation rates | D27: 1925 | E27: 1926 | F27: 1927 | G27: 1928 | H27: 1929 | I27: 1930 | J27: 1931 | K27: 1932 | L27: 1933 | M27: 1934 | N27: 1935 | O27: 1936 | P27: 1937 | Q27: 1938 | R27: 1939 | S27: 1940 | T27: 1941 | U27: 1942 | V27: 1943 | W27: 1944 | X27: 1945 | Y27: 1946 | Z27: 1947 | AA27: 1948 | AB27: 1949 | AC27: 1950 | AD27: 1951 | AE27: 1952 | AF27: 1953 | AG27: 1954 | AH27: 1955 | AI27: 1956 | AJ27: 1957 | AK27: 1958 | AL27: 1959 | AM27: 1960 | AN27: 1961 | AO27: 1962 | AP27: 1963 | AQ27: 1964 | AR27: 1965 | AS27: 1966 | AT27: 1967 | AU27: 1968 | AV27: 1969 | AW27: 1970 | AX27: 1971 | AY27: 1972 | AZ27: 1973 | BA27: 1974 | BB27: 1975 | BC27: 1976 | BD27: 1977 | BE27: 1978 | BF27: 1979 | BG27: 1980 | BH27: 1981 | BI27: 1982 | BJ27: 1983 | BK27: 1984 | BL27: 1985 | BM27: 1986 | BN27: 1987 | BO27: 1988 | BP27: 1989 | BQ27: 1990 | BR27: 1991 | BS27: 1992 | BT27: 1993 | BU27: 1994 | BV27: 1995 | BW27: 1996 | BX27: 1997 | BY27: 1998 | BZ27: 1999 | CA27: 2000 | CB27: 2001 | CC27: 2002 | CD27: 2003 | CE27: 2004 | CF27: 2005 | CG27: 2006 | CH27: 2007 | CI27: 2008 | CJ27: 2009 | CK27: 2010 | CL27: 2011
A28: Description | B28: Source | C28: Variable
A29: BEA 1993 Current-Cost Net stock | B29: BEA 1993, Table A13 | C29: KNCbea93 | D29: 77.769 | E29: 79.727 | F29: 80.892 | G29: 81.55 | H29: 81.369 | I29: 76.628 | J29: 68.367 | K29: 61.955 | L29: 60.951 | M29: 61.071 | N29: 61.096 | O29: 64.147 | P29: 67.517 | Q29: 66.281 | R29: 66.356 | S29: 69.879 | T29: 76.541 | U29: 80.512 | V29: 81.242 | W29: 82.345 | X29: 90.328 | Y29: 109.554 | Z29: 131.622 | AA29: 146.79 | AB29: 155.144 | AC29: 171.295 | AD29: 189.284 | AE29: 201.502 | AF29: 213.013 | AG29: 222.866 | AH29: 243.021 | AI29: 271.506 | AJ29: 292.041 | AK29: 301.41 | AL29: 314.077 | AM29: 323.054 | AN29: 331.447 | AO29: 343.819 | AP29: 357.177 | AQ29: 377.34 | AR29: 407.794 | AS29: 450.093 | AT29: 489.841 | AU29: 543.968 | AV29: 602.442 | AW29: 665.399 | AX29: 731.546 | AY29: 812.716 | AZ29: 922.601 | BA29: 1107.313 | BB29: 1252.398 | BC29: 1369.168 | BD29: 1520.544 | BE29: 1723.549 | BF29: 1976.173 | BG29: 2277.833 | BH29: 2579.67 | BI29: 2756.942 | BJ29: 2844.878 | BK29: 2993.218 | BL29: 3158.155 | BM29: 3317.184 | BN29: 3459.685 | BO29: 3681.151 | BP29: 3886.439
A30: BEA 1993 Constant-Cost Net stock (1987-$) | B30: BEA 1993, Table A12 | C30: KNRbea93 | D30: 822.004 | E30: 841.003 | F30: 855.083 | G30: 867.516 | H30: 887.887 | I30: 895.364 | J30: 879.613 | K30: 848.424 | L30: 816.242 | M30: 790.377 | N30: 769.43 | O30: 760.488 | P30: 759.942 | Q30: 745.033 | R30: 733.611 | S30: 732.947 | T30: 740.909 | U30: 728.618 | V30: 709.837 | W30: 701.423 | X30: 711.493 | Y30: 741.333 | Z30: 777.865 | AA30: 815.055 | AB30: 838.928 | AC30: 866.531 | AD30: 901.859 | AE30: 937.206 | AF30: 976.67 | AG30: 1009.261 | AH30: 1046.118 | AI30: 1094.62 | AJ30: 1140.899 | AK30: 1163.212 | AL30: 1191.814 | AM30: 1227.248 | AN30: 1259.146 | AO30: 1297.596 | AP30: 1339.206 | AQ30: 1394.866 | AR30: 1472.725 | AS30: 1563.775 | AT30: 1645.171 | AU30: 1734.351 | AV30: 1830.371 | AW30: 1912.185 | AX30: 1982.783 | AY30: 2055.337 | AZ30: 2157.155 | BA30: 2258.035 | BB30: 2320.562 | BC30: 2380.386 | BD30: 2457.278 | BE30: 2559.33 | BF30: 2678.474 | BG30: 2787.287 | BH30: 2894.056 | BI30: 2970.881 | BJ30: 3028.835 | BK30: 3130.834 | BL30: 3253.706 | BM30: 3344.065 | BN30: 3415.174 | BO30: 3492.368 | BP30: 3574.711
A31: BEA 1993 Implicit Price Deflator, Net Stock (1985 = 100) | B31: KNCbea93*100/KNRbea93 | C31: pKNbea93 | D31: =D29*100/D30 -> 9.4609029 | E31: =E29*100/E30 -> 9.47999 | F31: =F29*100/F30 -> 9.4601343 | G31: =G29*100/G30 -> 9.400403 | H31: =H29*100/H30 -> 9.1643419 | I31: =I29*100/I30 -> 8.558307 | J31: =J29*100/J30 -> 7.7723954 | K31: =K29*100/K30 -> 7.302363 | ... BP31: =BP29*100/BP30 -> 108.72037
